DEBUG    temporalio.worker._activity:_activity.py:276 Running activity wait_forever (token b'\n$e6d2a310-ce30-4dfe-87db-9ed829a8df47\x12-workflow-75af070b-e484-4540-904e-ed28d10f6a09\x1a$0a39060b-ec94-4a45-8726-7553fcc901b7 \x05(\x012\x011B\x0cwait_foreverJ\x08\x08\x01\x10\xc5\xa4@\x18\x01')
DEBUG    temporalio.activity:_activity.py:440 Starting activity ({'activity_id': '1', 'activity_type': 'wait_forever', 'attempt': 1, 'namespace': 'default', 'task_queue': '7fa489e1-81e7-46ab-bd16-b826f92389fa', 'workflow_id': 'workflow-75af070b-e484-4540-904e-ed28d10f6a09', 'workflow_run_id': '0a39060b-ec94-4a45-8726-7553fcc901b7', 'workflow_type': 'UncaughtCancelWorkflow'})
DEBUG    temporalio.worker._workflow_instance:_workflow_instance.py:1788 Workflow raised failure with run ID 0a39060b-ec94-4a45-8726-7553fcc901b7
temporalio.exceptions.CancelledError: Cancelled

The above exception was the direct cause of the following exception:

Traceback (most recent call last):
  File "/home/runner/work/sdk-python/sdk-python/temporalio/worker/_workflow_instance.py", line 1767, in _run_top_level_workflow_function
    await coro
  File "/home/runner/work/sdk-python/sdk-python/temporalio/worker/_workflow_instance.py", line 831, in run_workflow
    result = await self._inbound.execute_workflow(input)
             ^^^^^^^^^^^^^^^^^^^^^^^^^^^^^^^^^^^^^^^^^^^
  File "/home/runner/work/sdk-python/sdk-python/temporalio/testing/_workflow.py", line 493, in execute_workflow
    return await super().execute_workflow(input)
           ^^^^^^^^^^^^^^^^^^^^^^^^^^^^^^^^^^^^^
  File "/home/runner/work/sdk-python/sdk-python/temporalio/worker/_interceptor.py", line 328, in execute_workflow
    return await self.next.execute_workflow(input)
           ^^^^^^^^^^^^^^^^^^^^^^^^^^^^^^^^^^^^^^^
  File "/home/runner/work/sdk-python/sdk-python/temporalio/worker/_workflow_instance.py", line 2099, in execute_workflow
    return await input.run_fn(*args)
           ^^^^^^^^^^^^^^^^^^^^^^^^^
  File "/home/runner/work/sdk-python/sdk-python/tests/worker/test_workflow.py", line 1046, in run
    await workflow.execute_activity(
  File "/home/runner/work/sdk-python/sdk-python/temporalio/workflow.py", line 2011, in execute_activity
    return await _Runtime.current().workflow_start_activity(
           ^^^^^^^^^^^^^^^^^^^^^^^^^^^^^^^^^^^^^^^^^^^^^^^^^
  File "/home/runner/work/sdk-python/sdk-python/temporalio/worker/_workflow_instance.py", line 1423, in run_activity
    return await asyncio.shield(handle._result_fut)
           ^^^^^^^^^^^^^^^^^^^^^^^^^^^^^^^^^^^^^^^^
temporalio.exceptions.ActivityError: Activity cancelled
INFO     temporalio.worker._worker:_worker.py:523 Beginning worker shutdown, will wait 0:00:00 before cancelling activities
DEBUG    temporalio.worker._activity:_activity.py:216 Cancelling activity b'\n$e6d2a310-ce30-4dfe-87db-9ed829a8df47\x12-workflow-75af070b-e484-4540-904e-ed28d10f6a09\x1a$0a39060b-ec94-4a45-8726-7553fcc901b7 \x05(\x012\x011B\x0cwait_foreverJ\x08\x08\x01\x10\xc5\xa4@\x18\x01', reason: 3
DEBUG    temporalio.activity:_activity.py:486 Completing as cancelled ({'activity_id': '1', 'activity_type': 'wait_forever', 'attempt': 1, 'namespace': 'default', 'task_queue': '7fa489e1-81e7-46ab-bd16-b826f92389fa', 'workflow_id': 'workflow-75af070b-e484-4540-904e-ed28d10f6a09', 'workflow_run_id': '0a39060b-ec94-4a45-8726-7553fcc901b7', 'workflow_type': 'UncaughtCancelWorkflow'})
DEBUG    temporalio.worker._activity:_activity.py:527 Completing activity with completion: task_token: "\n$e6d2a310-ce30-4dfe-87db-9ed829a8df47\022-workflow-75af070b-e484-4540-904e-ed28d10f6a09\032$0a39060b-ec94-4a45-8726-7553fcc901b7 \005(\0012\0011B\014wait_foreverJ\010\010\001\020\305\244@\030\001"
result {
  cancelled {
    failure {
      message: "Cancelled"
      canceled_failure_info {
      }
    }
  }
}