WARNING  temporalio.worker.workflow_sandbox._restrictions:_restrictions.py:783 __call__ on os.getcwd restricted
DEBUG    temporalio.worker._workflow_instance:_workflow_instance.py:1788 Workflow raised failure with run ID dfc7fca1-2730-423d-8a73-c25aee219049
Traceback (most recent call last):
  File "/home/runner/work/sdk-python/sdk-python/tests/worker/workflow_sandbox/test_runner.py", line 149, in run
    exec(code)
  File "<string>", line 2, in <module>
  File "/home/runner/work/sdk-python/sdk-python/temporalio/worker/workflow_sandbox/_restrictions.py", line 964, in __call__
    state.assert_child_not_restricted("__call__")
  File "/home/runner/work/sdk-python/sdk-python/temporalio/worker/workflow_sandbox/_restrictions.py", line 792, in assert_child_not_restricted
    raise RestrictedWorkflowAccessError(
temporalio.worker.workflow_sandbox._restrictions.RestrictedWorkflowAccessError: Cannot access os.getcwd.__call__ from inside a workflow. If this is code from a module not used in a workflow or known to only be used deterministically from a workflow, mark the import as pass through.

The above exception was the direct cause of the following exception:

Traceback (most recent call last):
  File "/home/runner/work/sdk-python/sdk-python/temporalio/worker/_workflow_instance.py", line 1767, in _run_top_level_workflow_function
    await coro
  File "/home/runner/work/sdk-python/sdk-python/temporalio/worker/_workflow_instance.py", line 831, in run_workflow
    result = await self._inbound.execute_workflow(input)
  File "/home/runner/work/sdk-python/sdk-python/temporalio/testing/_workflow.py", line 493, in execute_workflow
    return await super().execute_workflow(input)
  File "/home/runner/work/sdk-python/sdk-python/temporalio/worker/_interceptor.py", line 328, in execute_workflow
    return await self.next.execute_workflow(input)
  File "/home/runner/work/sdk-python/sdk-python/temporalio/worker/_workflow_instance.py", line 2099, in execute_workflow
    return await input.run_fn(*args)
  File "/home/runner/work/sdk-python/sdk-python/tests/worker/workflow_sandbox/test_runner.py", line 151, in run
    raise ApplicationError(
temporalio.exceptions.ApplicationError: RestrictedWorkflowAccessError: Cannot access os.getcwd.__call__ from inside a workflow. If this is code from a module not used in a workflow or known to only be used deterministically from a workflow, mark the import as pass through.
WARNING  temporalio.worker.workflow_sandbox._restrictions:_restrictions.py:783 __call__ on os.getcwd restricted
DEBUG    temporalio.worker._workflow_instance:_workflow_instance.py:1788 Workflow raised failure with run ID 6a69458c-a65e-473a-a3c0-82d666a66e71
Traceback (most recent call last):
  File "/home/runner/work/sdk-python/sdk-python/tests/worker/workflow_sandbox/test_runner.py", line 149, in run
    exec(code)
  File "<string>", line 3, in <module>
  File "/home/runner/work/sdk-python/sdk-python/temporalio/worker/workflow_sandbox/_restrictions.py", line 964, in __call__
    state.assert_child_not_restricted("__call__")
  File "/home/runner/work/sdk-python/sdk-python/temporalio/worker/workflow_sandbox/_restrictions.py", line 792, in assert_child_not_restricted
    raise RestrictedWorkflowAccessError(
temporalio.worker.workflow_sandbox._restrictions.RestrictedWorkflowAccessError: Cannot access os.getcwd.__call__ from inside a workflow. If this is code from a module not used in a workflow or known to only be used deterministically from a workflow, mark the import as pass through.

The above exception was the direct cause of the following exception:

Traceback (most recent call last):
  File "/home/runner/work/sdk-python/sdk-python/temporalio/worker/_workflow_instance.py", line 1767, in _run_top_level_workflow_function
    await coro
  File "/home/runner/work/sdk-python/sdk-python/temporalio/worker/_workflow_instance.py", line 831, in run_workflow
    result = await self._inbound.execute_workflow(input)
  File "/home/runner/work/sdk-python/sdk-python/temporalio/testing/_workflow.py", line 493, in execute_workflow
    return await super().execute_workflow(input)
  File "/home/runner/work/sdk-python/sdk-python/temporalio/worker/_interceptor.py", line 328, in execute_workflow
    return await self.next.execute_workflow(input)
  File "/home/runner/work/sdk-python/sdk-python/temporalio/worker/_workflow_instance.py", line 2099, in execute_workflow
    return await input.run_fn(*args)
  File "/home/runner/work/sdk-python/sdk-python/tests/worker/workflow_sandbox/test_runner.py", line 151, in run
    raise ApplicationError(
temporalio.exceptions.ApplicationError: RestrictedWorkflowAccessError: Cannot access os.getcwd.__call__ from inside a workflow. If this is code from a module not used in a workflow or known to only be used deterministically from a workflow, mark the import as pass through.
WARNING  temporalio.worker.workflow_sandbox._restrictions:_restrictions.py:783 __call__ on glob.glob restricted
DEBUG    temporalio.worker._workflow_instance:_workflow_instance.py:1788 Workflow raised failure with run ID 67b58af4-3b2b-4d8b-9a84-a10c440cac8c
Traceback (most recent call last):
  File "/home/runner/work/sdk-python/sdk-python/tests/worker/workflow_sandbox/test_runner.py", line 149, in run
    exec(code)
  File "<string>", line 2, in <module>
  File "/home/runner/work/sdk-python/sdk-python/temporalio/worker/workflow_sandbox/_restrictions.py", line 964, in __call__
    state.assert_child_not_restricted("__call__")
  File "/home/runner/work/sdk-python/sdk-python/temporalio/worker/workflow_sandbox/_restrictions.py", line 792, in assert_child_not_restricted
    raise RestrictedWorkflowAccessError(
temporalio.worker.workflow_sandbox._restrictions.RestrictedWorkflowAccessError: Cannot access glob.glob.__call__ from inside a workflow. If this is code from a module not used in a workflow or known to only be used deterministically from a workflow, mark the import as pass through.

The above exception was the direct cause of the following exception:

Traceback (most recent call last):
  File "/home/runner/work/sdk-python/sdk-python/temporalio/worker/_workflow_instance.py", line 1767, in _run_top_level_workflow_function
    await coro
  File "/home/runner/work/sdk-python/sdk-python/temporalio/worker/_workflow_instance.py", line 831, in run_workflow
    result = await self._inbound.execute_workflow(input)
  File "/home/runner/work/sdk-python/sdk-python/temporalio/testing/_workflow.py", line 493, in execute_workflow
    return await super().execute_workflow(input)
  File "/home/runner/work/sdk-python/sdk-python/temporalio/worker/_interceptor.py", line 328, in execute_workflow
    return await self.next.execute_workflow(input)
  File "/home/runner/work/sdk-python/sdk-python/temporalio/worker/_workflow_instance.py", line 2099, in execute_workflow
    return await input.run_fn(*args)
  File "/home/runner/work/sdk-python/sdk-python/tests/worker/workflow_sandbox/test_runner.py", line 151, in run
    raise ApplicationError(
temporalio.exceptions.ApplicationError: RestrictedWorkflowAccessError: Cannot access glob.glob.__call__ from inside a workflow. If this is code from a module not used in a workflow or known to only be used deterministically from a workflow, mark the import as pass through.
WARNING  temporalio.worker.workflow_sandbox._restrictions:_restrictions.py:783 name on os restricted
DEBUG    temporalio.worker._workflow_instance:_workflow_instance.py:1788 Workflow raised failure with run ID ae79a011-a94c-4fb1-9dd4-35659034482d
Traceback (most recent call last):
  File "/home/runner/work/sdk-python/sdk-python/tests/worker/workflow_sandbox/test_runner.py", line 149, in run
    exec(code)
  File "<string>", line 2, in <module>
  File "/home/runner/work/sdk-python/sdk-python/temporalio/worker/workflow_sandbox/_restrictions.py", line 942, in __getattribute__
    state.assert_child_not_restricted(__name)
  File "/home/runner/work/sdk-python/sdk-python/temporalio/worker/workflow_sandbox/_restrictions.py", line 792, in assert_child_not_restricted
    raise RestrictedWorkflowAccessError(
temporalio.worker.workflow_sandbox._restrictions.RestrictedWorkflowAccessError: Cannot access os.name from inside a workflow. If this is code from a module not used in a workflow or known to only be used deterministically from a workflow, mark the import as pass through.

The above exception was the direct cause of the following exception:

Traceback (most recent call last):
  File "/home/runner/work/sdk-python/sdk-python/temporalio/worker/_workflow_instance.py", line 1767, in _run_top_level_workflow_function
    await coro
  File "/home/runner/work/sdk-python/sdk-python/temporalio/worker/_workflow_instance.py", line 831, in run_workflow
    result = await self._inbound.execute_workflow(input)
  File "/home/runner/work/sdk-python/sdk-python/temporalio/testing/_workflow.py", line 493, in execute_workflow
    return await super().execute_workflow(input)
  File "/home/runner/work/sdk-python/sdk-python/temporalio/worker/_interceptor.py", line 328, in execute_workflow
    return await self.next.execute_workflow(input)
  File "/home/runner/work/sdk-python/sdk-python/temporalio/worker/_workflow_instance.py", line 2099, in execute_workflow
    return await input.run_fn(*args)
  File "/home/runner/work/sdk-python/sdk-python/tests/worker/workflow_sandbox/test_runner.py", line 151, in run
    raise ApplicationError(
temporalio.exceptions.ApplicationError: RestrictedWorkflowAccessError: Cannot access os.name from inside a workflow. If this is code from a module not used in a workflow or known to only be used deterministically from a workflow, mark the import as pass through.
DEBUG    temporalio.worker._workflow_instance:_workflow_instance.py:1788 Workflow raised failure with run ID a927a265-9179-48d7-b594-7b42f80a558f
Traceback (most recent call last):
  File "/home/runner/work/sdk-python/sdk-python/tests/worker/workflow_sandbox/test_runner.py", line 149, in run
    exec(code)
  File "<string>", line 1, in <module>
  File "/home/runner/work/sdk-python/sdk-python/temporalio/worker/workflow_sandbox/_importer.py", line 441, in __call__
    return self.current(*args, **kwargs)
  File "/home/runner/work/sdk-python/sdk-python/temporalio/worker/workflow_sandbox/_importer.py", line 94, in restrict_built_in
    raise RestrictedWorkflowAccessError(f"__builtins__.{name}")
temporalio.worker.workflow_sandbox._restrictions.RestrictedWorkflowAccessError: Cannot access __builtins__.open from inside a workflow. If this is code from a module not used in a workflow or known to only be used deterministically from a workflow, mark the import as pass through.

The above exception was the direct cause of the following exception:

Traceback (most recent call last):
  File "/home/runner/work/sdk-python/sdk-python/temporalio/worker/_workflow_instance.py", line 1767, in _run_top_level_workflow_function
    await coro
  File "/home/runner/work/sdk-python/sdk-python/temporalio/worker/_workflow_instance.py", line 831, in run_workflow
    result = await self._inbound.execute_workflow(input)
  File "/home/runner/work/sdk-python/sdk-python/temporalio/testing/_workflow.py", line 493, in execute_workflow
    return await super().execute_workflow(input)
  File "/home/runner/work/sdk-python/sdk-python/temporalio/worker/_interceptor.py", line 328, in execute_workflow
    return await self.next.execute_workflow(input)
  File "/home/runner/work/sdk-python/sdk-python/temporalio/worker/_workflow_instance.py", line 2099, in execute_workflow
    return await input.run_fn(*args)
  File "/home/runner/work/sdk-python/sdk-python/tests/worker/workflow_sandbox/test_runner.py", line 151, in run
    raise ApplicationError(
temporalio.exceptions.ApplicationError: RestrictedWorkflowAccessError: Cannot access __builtins__.open from inside a workflow. If this is code from a module not used in a workflow or known to only be used deterministically from a workflow, mark the import as pass through.
WARNING  temporalio.worker.workflow_sandbox._restrictions:_restrictions.py:783 __call__ on random.choice restricted
DEBUG    temporalio.worker._workflow_instance:_workflow_instance.py:1788 Workflow raised failure with run ID 8f7674bd-ee06-4f10-8b06-ce925d417372
Traceback (most recent call last):
  File "/home/runner/work/sdk-python/sdk-python/tests/worker/workflow_sandbox/test_runner.py", line 149, in run
    exec(code)
  File "<string>", line 1, in <module>
  File "/home/runner/work/sdk-python/sdk-python/temporalio/worker/workflow_sandbox/_importer.py", line 441, in __call__
    return self.current(*args, **kwargs)
  File "/home/runner/work/sdk-python/sdk-python/temporalio/worker/workflow_sandbox/_importer.py", line 234, in _import
    mod = importlib.__import__(name, globals, locals, fromlist, level)
  File "<frozen importlib._bootstrap>", line 1093, in __import__
  File "<frozen importlib._bootstrap>", line 1014, in _gcd_import
  File "<frozen importlib._bootstrap>", line 991, in _find_and_load
  File "<frozen importlib._bootstrap>", line 975, in _find_and_load_unlocked
  File "<frozen importlib._bootstrap>", line 671, in _load_unlocked
  File "<frozen importlib._bootstrap_external>", line 843, in exec_module
  File "<frozen importlib._bootstrap>", line 219, in _call_with_frames_removed
  File "/home/runner/work/sdk-python/sdk-python/tests/worker/workflow_sandbox/testmodules/module_calling_invalid.py", line 3, in <module>
    random.choice(["foo", "bar"])
  File "/home/runner/work/sdk-python/sdk-python/temporalio/worker/workflow_sandbox/_restrictions.py", line 964, in __call__
    state.assert_child_not_restricted("__call__")
  File "/home/runner/work/sdk-python/sdk-python/temporalio/worker/workflow_sandbox/_restrictions.py", line 792, in assert_child_not_restricted
    raise RestrictedWorkflowAccessError(
temporalio.worker.workflow_sandbox._restrictions.RestrictedWorkflowAccessError: Cannot access random.choice.__call__ from inside a workflow. If this is code from a module not used in a workflow or known to only be used deterministically from a workflow, mark the import as pass through.

The above exception was the direct cause of the following exception:

Traceback (most recent call last):
  File "/home/runner/work/sdk-python/sdk-python/temporalio/worker/_workflow_instance.py", line 1767, in _run_top_level_workflow_function
    await coro
  File "/home/runner/work/sdk-python/sdk-python/temporalio/worker/_workflow_instance.py", line 831, in run_workflow
    result = await self._inbound.execute_workflow(input)
  File "/home/runner/work/sdk-python/sdk-python/temporalio/testing/_workflow.py", line 493, in execute_workflow
    return await super().execute_workflow(input)
  File "/home/runner/work/sdk-python/sdk-python/temporalio/worker/_interceptor.py", line 328, in execute_workflow
    return await self.next.execute_workflow(input)
  File "/home/runner/work/sdk-python/sdk-python/temporalio/worker/_workflow_instance.py", line 2099, in execute_workflow
    return await input.run_fn(*args)
  File "/home/runner/work/sdk-python/sdk-python/tests/worker/workflow_sandbox/test_runner.py", line 151, in run
    raise ApplicationError(
temporalio.exceptions.ApplicationError: RestrictedWorkflowAccessError: Cannot access random.choice.__call__ from inside a workflow. If this is code from a module not used in a workflow or known to only be used deterministically from a workflow, mark the import as pass through.
WARNING  temporalio.worker.workflow_sandbox._restrictions:_restrictions.py:783 __call__ on datetime.date.today restricted
DEBUG    temporalio.worker._workflow_instance:_workflow_instance.py:1788 Workflow raised failure with run ID 2f2e8598-268b-4481-84c7-286e38512db8
Traceback (most recent call last):
  File "/home/runner/work/sdk-python/sdk-python/tests/worker/workflow_sandbox/test_runner.py", line 149, in run
    exec(code)
  File "<string>", line 2, in <module>
  File "/home/runner/work/sdk-python/sdk-python/temporalio/worker/workflow_sandbox/_restrictions.py", line 964, in __call__
    state.assert_child_not_restricted("__call__")
  File "/home/runner/work/sdk-python/sdk-python/temporalio/worker/workflow_sandbox/_restrictions.py", line 792, in assert_child_not_restricted
    raise RestrictedWorkflowAccessError(
temporalio.worker.workflow_sandbox._restrictions.RestrictedWorkflowAccessError: Cannot access datetime.date.today.__call__ from inside a workflow. If this is code from a module not used in a workflow or known to only be used deterministically from a workflow, mark the import as pass through.

The above exception was the direct cause of the following exception:

Traceback (most recent call last):
  File "/home/runner/work/sdk-python/sdk-python/temporalio/worker/_workflow_instance.py", line 1767, in _run_top_level_workflow_function
    await coro
  File "/home/runner/work/sdk-python/sdk-python/temporalio/worker/_workflow_instance.py", line 831, in run_workflow
    result = await self._inbound.execute_workflow(input)
  File "/home/runner/work/sdk-python/sdk-python/temporalio/testing/_workflow.py", line 493, in execute_workflow
    return await super().execute_workflow(input)
  File "/home/runner/work/sdk-python/sdk-python/temporalio/worker/_interceptor.py", line 328, in execute_workflow
    return await self.next.execute_workflow(input)
  File "/home/runner/work/sdk-python/sdk-python/temporalio/worker/_workflow_instance.py", line 2099, in execute_workflow
    return await input.run_fn(*args)
  File "/home/runner/work/sdk-python/sdk-python/tests/worker/workflow_sandbox/test_runner.py", line 151, in run
    raise ApplicationError(
temporalio.exceptions.ApplicationError: RestrictedWorkflowAccessError: Cannot access datetime.date.today.__call__ from inside a workflow. If this is code from a module not used in a workflow or known to only be used deterministically from a workflow, mark the import as pass through.
WARNING  temporalio.worker.workflow_sandbox._restrictions:_restrictions.py:783 __call__ on datetime.datetime.now restricted
DEBUG    temporalio.worker._workflow_instance:_workflow_instance.py:1788 Workflow raised failure with run ID c58ad04c-e864-49f1-bd91-fc3c8b6fa4a3
Traceback (most recent call last):
  File "/home/runner/work/sdk-python/sdk-python/tests/worker/workflow_sandbox/test_runner.py", line 149, in run
    exec(code)
  File "<string>", line 2, in <module>
  File "/home/runner/work/sdk-python/sdk-python/temporalio/worker/workflow_sandbox/_restrictions.py", line 964, in __call__
    state.assert_child_not_restricted("__call__")
  File "/home/runner/work/sdk-python/sdk-python/temporalio/worker/workflow_sandbox/_restrictions.py", line 792, in assert_child_not_restricted
    raise RestrictedWorkflowAccessError(
temporalio.worker.workflow_sandbox._restrictions.RestrictedWorkflowAccessError: Cannot access datetime.datetime.now.__call__ from inside a workflow. If this is code from a module not used in a workflow or known to only be used deterministically from a workflow, mark the import as pass through.

The above exception was the direct cause of the following exception:

Traceback (most recent call last):
  File "/home/runner/work/sdk-python/sdk-python/temporalio/worker/_workflow_instance.py", line 1767, in _run_top_level_workflow_function
    await coro
  File "/home/runner/work/sdk-python/sdk-python/temporalio/worker/_workflow_instance.py", line 831, in run_workflow
    result = await self._inbound.execute_workflow(input)
  File "/home/runner/work/sdk-python/sdk-python/temporalio/testing/_workflow.py", line 493, in execute_workflow
    return await super().execute_workflow(input)
  File "/home/runner/work/sdk-python/sdk-python/temporalio/worker/_interceptor.py", line 328, in execute_workflow
    return await self.next.execute_workflow(input)
  File "/home/runner/work/sdk-python/sdk-python/temporalio/worker/_workflow_instance.py", line 2099, in execute_workflow
    return await input.run_fn(*args)
  File "/home/runner/work/sdk-python/sdk-python/tests/worker/workflow_sandbox/test_runner.py", line 151, in run
    raise ApplicationError(
temporalio.exceptions.ApplicationError: RestrictedWorkflowAccessError: Cannot access datetime.datetime.now.__call__ from inside a workflow. If this is code from a module not used in a workflow or known to only be used deterministically from a workflow, mark the import as pass through.
WARNING  temporalio.worker.workflow_sandbox._restrictions:_restrictions.py:783 foo on os.environ restricted
DEBUG    temporalio.worker._workflow_instance:_workflow_instance.py:1788 Workflow raised failure with run ID a543d66f-eb16-4ec9-8e11-995ba42cc41a
Traceback (most recent call last):
  File "/home/runner/work/sdk-python/sdk-python/tests/worker/workflow_sandbox/test_runner.py", line 149, in run
    exec(code)
  File "<string>", line 2, in <module>
  File "/home/runner/work/sdk-python/sdk-python/temporalio/worker/workflow_sandbox/_restrictions.py", line 942, in __getattribute__
    state.assert_child_not_restricted(__name)
  File "/home/runner/work/sdk-python/sdk-python/temporalio/worker/workflow_sandbox/_restrictions.py", line 792, in assert_child_not_restricted
    raise RestrictedWorkflowAccessError(
temporalio.worker.workflow_sandbox._restrictions.RestrictedWorkflowAccessError: Cannot access os.environ.foo from inside a workflow. If this is code from a module not used in a workflow or known to only be used deterministically from a workflow, mark the import as pass through.

The above exception was the direct cause of the following exception:

Traceback (most recent call last):
  File "/home/runner/work/sdk-python/sdk-python/temporalio/worker/_workflow_instance.py", line 1767, in _run_top_level_workflow_function
    await coro
  File "/home/runner/work/sdk-python/sdk-python/temporalio/worker/_workflow_instance.py", line 831, in run_workflow
    result = await self._inbound.execute_workflow(input)
  File "/home/runner/work/sdk-python/sdk-python/temporalio/testing/_workflow.py", line 493, in execute_workflow
    return await super().execute_workflow(input)
  File "/home/runner/work/sdk-python/sdk-python/temporalio/worker/_interceptor.py", line 328, in execute_workflow
    return await self.next.execute_workflow(input)
  File "/home/runner/work/sdk-python/sdk-python/temporalio/worker/_workflow_instance.py", line 2099, in execute_workflow
    return await input.run_fn(*args)
  File "/home/runner/work/sdk-python/sdk-python/tests/worker/workflow_sandbox/test_runner.py", line 151, in run
    raise ApplicationError(
temporalio.exceptions.ApplicationError: RestrictedWorkflowAccessError: Cannot access os.environ.foo from inside a workflow. If this is code from a module not used in a workflow or known to only be used deterministically from a workflow, mark the import as pass through.
WARNING  temporalio.worker.workflow_sandbox._restrictions:_restrictions.py:783 __call__ on os.getenv restricted
DEBUG    temporalio.worker._workflow_instance:_workflow_instance.py:1788 Workflow raised failure with run ID 2533337f-fb7b-4943-93b3-c296eaf483c1
Traceback (most recent call last):
  File "/home/runner/work/sdk-python/sdk-python/tests/worker/workflow_sandbox/test_runner.py", line 149, in run
    exec(code)
  File "<string>", line 2, in <module>
  File "/home/runner/work/sdk-python/sdk-python/temporalio/worker/workflow_sandbox/_restrictions.py", line 964, in __call__
    state.assert_child_not_restricted("__call__")
  File "/home/runner/work/sdk-python/sdk-python/temporalio/worker/workflow_sandbox/_restrictions.py", line 792, in assert_child_not_restricted
    raise RestrictedWorkflowAccessError(
temporalio.worker.workflow_sandbox._restrictions.RestrictedWorkflowAccessError: Cannot access os.getenv.__call__ from inside a workflow. If this is code from a module not used in a workflow or known to only be used deterministically from a workflow, mark the import as pass through.

The above exception was the direct cause of the following exception:

Traceback (most recent call last):
  File "/home/runner/work/sdk-python/sdk-python/temporalio/worker/_workflow_instance.py", line 1767, in _run_top_level_workflow_function
    await coro
  File "/home/runner/work/sdk-python/sdk-python/temporalio/worker/_workflow_instance.py", line 831, in run_workflow
    result = await self._inbound.execute_workflow(input)
  File "/home/runner/work/sdk-python/sdk-python/temporalio/testing/_workflow.py", line 493, in execute_workflow
    return await super().execute_workflow(input)
  File "/home/runner/work/sdk-python/sdk-python/temporalio/worker/_interceptor.py", line 328, in execute_workflow
    return await self.next.execute_workflow(input)
  File "/home/runner/work/sdk-python/sdk-python/temporalio/worker/_workflow_instance.py", line 2099, in execute_workflow
    return await input.run_fn(*args)
  File "/home/runner/work/sdk-python/sdk-python/tests/worker/workflow_sandbox/test_runner.py", line 151, in run
    raise ApplicationError(
temporalio.exceptions.ApplicationError: RestrictedWorkflowAccessError: Cannot access os.getenv.__call__ from inside a workflow. If this is code from a module not used in a workflow or known to only be used deterministically from a workflow, mark the import as pass through.
WARNING  temporalio.worker.workflow_sandbox._restrictions:_restrictions.py:783 abspath on os.path restricted
DEBUG    temporalio.worker._workflow_instance:_workflow_instance.py:1788 Workflow raised failure with run ID b8284284-8324-446d-b355-5d48b37ae109
Traceback (most recent call last):
  File "/home/runner/work/sdk-python/sdk-python/tests/worker/workflow_sandbox/test_runner.py", line 149, in run
    exec(code)
  File "<string>", line 2, in <module>
  File "/home/runner/work/sdk-python/sdk-python/temporalio/worker/workflow_sandbox/_restrictions.py", line 942, in __getattribute__
    state.assert_child_not_restricted(__name)
  File "/home/runner/work/sdk-python/sdk-python/temporalio/worker/workflow_sandbox/_restrictions.py", line 792, in assert_child_not_restricted
    raise RestrictedWorkflowAccessError(
temporalio.worker.workflow_sandbox._restrictions.RestrictedWorkflowAccessError: Cannot access os.path.abspath from inside a workflow. If this is code from a module not used in a workflow or known to only be used deterministically from a workflow, mark the import as pass through.

The above exception was the direct cause of the following exception:

Traceback (most recent call last):
  File "/home/runner/work/sdk-python/sdk-python/temporalio/worker/_workflow_instance.py", line 1767, in _run_top_level_workflow_function
    await coro
  File "/home/runner/work/sdk-python/sdk-python/temporalio/worker/_workflow_instance.py", line 831, in run_workflow
    result = await self._inbound.execute_workflow(input)
  File "/home/runner/work/sdk-python/sdk-python/temporalio/testing/_workflow.py", line 493, in execute_workflow
    return await super().execute_workflow(input)
  File "/home/runner/work/sdk-python/sdk-python/temporalio/worker/_interceptor.py", line 328, in execute_workflow
    return await self.next.execute_workflow(input)
  File "/home/runner/work/sdk-python/sdk-python/temporalio/worker/_workflow_instance.py", line 2099, in execute_workflow
    return await input.run_fn(*args)
  File "/home/runner/work/sdk-python/sdk-python/tests/worker/workflow_sandbox/test_runner.py", line 151, in run
    raise ApplicationError(
temporalio.exceptions.ApplicationError: RestrictedWorkflowAccessError: Cannot access os.path.abspath from inside a workflow. If this is code from a module not used in a workflow or known to only be used deterministically from a workflow, mark the import as pass through.
WARNING  temporalio.worker.workflow_sandbox._restrictions:_restrictions.py:783 __call__ on random.choice restricted
DEBUG    temporalio.worker._workflow_instance:_workflow_instance.py:1788 Workflow raised failure with run ID 451d1f10-298a-427a-a567-7c96dcc34e9f
Traceback (most recent call last):
  File "/home/runner/work/sdk-python/sdk-python/tests/worker/workflow_sandbox/test_runner.py", line 149, in run
    exec(code)
  File "<string>", line 2, in <module>
  File "/home/runner/work/sdk-python/sdk-python/temporalio/worker/workflow_sandbox/_restrictions.py", line 964, in __call__
    state.assert_child_not_restricted("__call__")
  File "/home/runner/work/sdk-python/sdk-python/temporalio/worker/workflow_sandbox/_restrictions.py", line 792, in assert_child_not_restricted
    raise RestrictedWorkflowAccessError(
temporalio.worker.workflow_sandbox._restrictions.RestrictedWorkflowAccessError: Cannot access random.choice.__call__ from inside a workflow. If this is code from a module not used in a workflow or known to only be used deterministically from a workflow, mark the import as pass through.

The above exception was the direct cause of the following exception:

Traceback (most recent call last):
  File "/home/runner/work/sdk-python/sdk-python/temporalio/worker/_workflow_instance.py", line 1767, in _run_top_level_workflow_function
    await coro
  File "/home/runner/work/sdk-python/sdk-python/temporalio/worker/_workflow_instance.py", line 831, in run_workflow
    result = await self._inbound.execute_workflow(input)
  File "/home/runner/work/sdk-python/sdk-python/temporalio/testing/_workflow.py", line 493, in execute_workflow
    return await super().execute_workflow(input)
  File "/home/runner/work/sdk-python/sdk-python/temporalio/worker/_interceptor.py", line 328, in execute_workflow
    return await self.next.execute_workflow(input)
  File "/home/runner/work/sdk-python/sdk-python/temporalio/worker/_workflow_instance.py", line 2099, in execute_workflow
    return await input.run_fn(*args)
  File "/home/runner/work/sdk-python/sdk-python/tests/worker/workflow_sandbox/test_runner.py", line 151, in run
    raise ApplicationError(
temporalio.exceptions.ApplicationError: RestrictedWorkflowAccessError: Cannot access random.choice.__call__ from inside a workflow. If this is code from a module not used in a workflow or known to only be used deterministically from a workflow, mark the import as pass through.
WARNING  temporalio.worker.workflow_sandbox._restrictions:_restrictions.py:783 __call__ on secrets.choice restricted
DEBUG    temporalio.worker._workflow_instance:_workflow_instance.py:1788 Workflow raised failure with run ID d6bbb04c-c448-4ad5-945c-8efd44c49998
Traceback (most recent call last):
  File "/home/runner/work/sdk-python/sdk-python/tests/worker/workflow_sandbox/test_runner.py", line 149, in run
    exec(code)
  File "<string>", line 2, in <module>
  File "/home/runner/work/sdk-python/sdk-python/temporalio/worker/workflow_sandbox/_restrictions.py", line 964, in __call__
    state.assert_child_not_restricted("__call__")
  File "/home/runner/work/sdk-python/sdk-python/temporalio/worker/workflow_sandbox/_restrictions.py", line 792, in assert_child_not_restricted
    raise RestrictedWorkflowAccessError(
temporalio.worker.workflow_sandbox._restrictions.RestrictedWorkflowAccessError: Cannot access secrets.choice.__call__ from inside a workflow. If this is code from a module not used in a workflow or known to only be used deterministically from a workflow, mark the import as pass through.

The above exception was the direct cause of the following exception:

Traceback (most recent call last):
  File "/home/runner/work/sdk-python/sdk-python/temporalio/worker/_workflow_instance.py", line 1767, in _run_top_level_workflow_function
    await coro
  File "/home/runner/work/sdk-python/sdk-python/temporalio/worker/_workflow_instance.py", line 831, in run_workflow
    result = await self._inbound.execute_workflow(input)
  File "/home/runner/work/sdk-python/sdk-python/temporalio/testing/_workflow.py", line 493, in execute_workflow
    return await super().execute_workflow(input)
  File "/home/runner/work/sdk-python/sdk-python/temporalio/worker/_interceptor.py", line 328, in execute_workflow
    return await self.next.execute_workflow(input)
  File "/home/runner/work/sdk-python/sdk-python/temporalio/worker/_workflow_instance.py", line 2099, in execute_workflow
    return await input.run_fn(*args)
  File "/home/runner/work/sdk-python/sdk-python/tests/worker/workflow_sandbox/test_runner.py", line 151, in run
    raise ApplicationError(
temporalio.exceptions.ApplicationError: RestrictedWorkflowAccessError: Cannot access secrets.choice.__call__ from inside a workflow. If this is code from a module not used in a workflow or known to only be used deterministically from a workflow, mark the import as pass through.
WARNING  temporalio.worker.workflow_sandbox._restrictions:_restrictions.py:783 __call__ on threading.current_thread restricted
DEBUG    temporalio.worker._workflow_instance:_workflow_instance.py:1788 Workflow raised failure with run ID f90a264c-b7d8-40ea-a2bf-5f1047650542
Traceback (most recent call last):
  File "/home/runner/work/sdk-python/sdk-python/tests/worker/workflow_sandbox/test_runner.py", line 149, in run
    exec(code)
  File "<string>", line 2, in <module>
  File "/home/runner/work/sdk-python/sdk-python/temporalio/worker/workflow_sandbox/_restrictions.py", line 964, in __call__
    state.assert_child_not_restricted("__call__")
  File "/home/runner/work/sdk-python/sdk-python/temporalio/worker/workflow_sandbox/_restrictions.py", line 792, in assert_child_not_restricted
    raise RestrictedWorkflowAccessError(
temporalio.worker.workflow_sandbox._restrictions.RestrictedWorkflowAccessError: Cannot access threading.current_thread.__call__ from inside a workflow. If this is code from a module not used in a workflow or known to only be used deterministically from a workflow, mark the import as pass through.

The above exception was the direct cause of the following exception:

Traceback (most recent call last):
  File "/home/runner/work/sdk-python/sdk-python/temporalio/worker/_workflow_instance.py", line 1767, in _run_top_level_workflow_function
    await coro
  File "/home/runner/work/sdk-python/sdk-python/temporalio/worker/_workflow_instance.py", line 831, in run_workflow
    result = await self._inbound.execute_workflow(input)
  File "/home/runner/work/sdk-python/sdk-python/temporalio/testing/_workflow.py", line 493, in execute_workflow
    return await super().execute_workflow(input)
  File "/home/runner/work/sdk-python/sdk-python/temporalio/worker/_interceptor.py", line 328, in execute_workflow
    return await self.next.execute_workflow(input)
  File "/home/runner/work/sdk-python/sdk-python/temporalio/worker/_workflow_instance.py", line 2099, in execute_workflow
    return await input.run_fn(*args)
  File "/home/runner/work/sdk-python/sdk-python/tests/worker/workflow_sandbox/test_runner.py", line 151, in run
    raise ApplicationError(
temporalio.exceptions.ApplicationError: RestrictedWorkflowAccessError: Cannot access threading.current_thread.__call__ from inside a workflow. If this is code from a module not used in a workflow or known to only be used deterministically from a workflow, mark the import as pass through.
WARNING  temporalio.worker.workflow_sandbox._restrictions:_restrictions.py:783 __call__ on time.sleep restricted
DEBUG    temporalio.worker._workflow_instance:_workflow_instance.py:1788 Workflow raised failure with run ID 9e3d7eaa-d2bd-4f62-902f-c59eb86fb3a9
Traceback (most recent call last):
  File "/home/runner/work/sdk-python/sdk-python/tests/worker/workflow_sandbox/test_runner.py", line 149, in run
    exec(code)
  File "<string>", line 2, in <module>
  File "/home/runner/work/sdk-python/sdk-python/temporalio/worker/workflow_sandbox/_restrictions.py", line 964, in __call__
    state.assert_child_not_restricted("__call__")
  File "/home/runner/work/sdk-python/sdk-python/temporalio/worker/workflow_sandbox/_restrictions.py", line 792, in assert_child_not_restricted
    raise RestrictedWorkflowAccessError(
temporalio.worker.workflow_sandbox._restrictions.RestrictedWorkflowAccessError: Cannot access time.sleep.__call__ from inside a workflow. If this is code from a module not used in a workflow or known to only be used deterministically from a workflow, mark the import as pass through.

The above exception was the direct cause of the following exception:

Traceback (most recent call last):
  File "/home/runner/work/sdk-python/sdk-python/temporalio/worker/_workflow_instance.py", line 1767, in _run_top_level_workflow_function
    await coro
  File "/home/runner/work/sdk-python/sdk-python/temporalio/worker/_workflow_instance.py", line 831, in run_workflow
    result = await self._inbound.execute_workflow(input)
  File "/home/runner/work/sdk-python/sdk-python/temporalio/testing/_workflow.py", line 493, in execute_workflow
    return await super().execute_workflow(input)
  File "/home/runner/work/sdk-python/sdk-python/temporalio/worker/_interceptor.py", line 328, in execute_workflow
    return await self.next.execute_workflow(input)
  File "/home/runner/work/sdk-python/sdk-python/temporalio/worker/_workflow_instance.py", line 2099, in execute_workflow
    return await input.run_fn(*args)
  File "/home/runner/work/sdk-python/sdk-python/tests/worker/workflow_sandbox/test_runner.py", line 151, in run
    raise ApplicationError(
temporalio.exceptions.ApplicationError: RestrictedWorkflowAccessError: Cannot access time.sleep.__call__ from inside a workflow. If this is code from a module not used in a workflow or known to only be used deterministically from a workflow, mark the import as pass through.
WARNING  temporalio.worker.workflow_sandbox._restrictions:_restrictions.py:783 __call__ on concurrent.futures.ThreadPoolExecutor restricted
DEBUG    temporalio.worker._workflow_instance:_workflow_instance.py:1788 Workflow raised failure with run ID 90cf7186-1902-4eb5-a0cf-685836d349a5
Traceback (most recent call last):
  File "/home/runner/work/sdk-python/sdk-python/tests/worker/workflow_sandbox/test_runner.py", line 149, in run
    exec(code)
  File "<string>", line 2, in <module>
  File "/home/runner/work/sdk-python/sdk-python/temporalio/worker/workflow_sandbox/_restrictions.py", line 964, in __call__
    state.assert_child_not_restricted("__call__")
  File "/home/runner/work/sdk-python/sdk-python/temporalio/worker/workflow_sandbox/_restrictions.py", line 792, in assert_child_not_restricted
    raise RestrictedWorkflowAccessError(
temporalio.worker.workflow_sandbox._restrictions.RestrictedWorkflowAccessError: Cannot access concurrent.futures.ThreadPoolExecutor.__call__ from inside a workflow. If this is code from a module not used in a workflow or known to only be used deterministically from a workflow, mark the import as pass through.

The above exception was the direct cause of the following exception:

Traceback (most recent call last):
  File "/home/runner/work/sdk-python/sdk-python/temporalio/worker/_workflow_instance.py", line 1767, in _run_top_level_workflow_function
    await coro
  File "/home/runner/work/sdk-python/sdk-python/temporalio/worker/_workflow_instance.py", line 831, in run_workflow
    result = await self._inbound.execute_workflow(input)
  File "/home/runner/work/sdk-python/sdk-python/temporalio/testing/_workflow.py", line 493, in execute_workflow
    return await super().execute_workflow(input)
  File "/home/runner/work/sdk-python/sdk-python/temporalio/worker/_interceptor.py", line 328, in execute_workflow
    return await self.next.execute_workflow(input)
  File "/home/runner/work/sdk-python/sdk-python/temporalio/worker/_workflow_instance.py", line 2099, in execute_workflow
    return await input.run_fn(*args)
  File "/home/runner/work/sdk-python/sdk-python/tests/worker/workflow_sandbox/test_runner.py", line 151, in run
    raise ApplicationError(
temporalio.exceptions.ApplicationError: RestrictedWorkflowAccessError: Cannot access concurrent.futures.ThreadPoolExecutor.__call__ from inside a workflow. If this is code from a module not used in a workflow or known to only be used deterministically from a workflow, mark the import as pass through.
WARNING  temporalio.worker.workflow_sandbox._restrictions:_restrictions.py:783 __call__ on urllib.request.urlopen restricted
DEBUG    temporalio.worker._workflow_instance:_workflow_instance.py:1788 Workflow raised failure with run ID 9c07df38-6e68-4740-a945-42a23c8eabbb
Traceback (most recent call last):
  File "/home/runner/work/sdk-python/sdk-python/tests/worker/workflow_sandbox/test_runner.py", line 149, in run
    exec(code)
  File "<string>", line 2, in <module>
  File "/home/runner/work/sdk-python/sdk-python/temporalio/worker/workflow_sandbox/_restrictions.py", line 964, in __call__
    state.assert_child_not_restricted("__call__")
  File "/home/runner/work/sdk-python/sdk-python/temporalio/worker/workflow_sandbox/_restrictions.py", line 792, in assert_child_not_restricted
    raise RestrictedWorkflowAccessError(
temporalio.worker.workflow_sandbox._restrictions.RestrictedWorkflowAccessError: Cannot access urllib.request.urlopen.__call__ from inside a workflow. If this is code from a module not used in a workflow or known to only be used deterministically from a workflow, mark the import as pass through.

The above exception was the direct cause of the following exception:

Traceback (most recent call last):
  File "/home/runner/work/sdk-python/sdk-python/temporalio/worker/_workflow_instance.py", line 1767, in _run_top_level_workflow_function
    await coro
  File "/home/runner/work/sdk-python/sdk-python/temporalio/worker/_workflow_instance.py", line 831, in run_workflow
    result = await self._inbound.execute_workflow(input)
  File "/home/runner/work/sdk-python/sdk-python/temporalio/testing/_workflow.py", line 493, in execute_workflow
    return await super().execute_workflow(input)
  File "/home/runner/work/sdk-python/sdk-python/temporalio/worker/_interceptor.py", line 328, in execute_workflow
    return await self.next.execute_workflow(input)
  File "/home/runner/work/sdk-python/sdk-python/temporalio/worker/_workflow_instance.py", line 2099, in execute_workflow
    return await input.run_fn(*args)
  File "/home/runner/work/sdk-python/sdk-python/tests/worker/workflow_sandbox/test_runner.py", line 151, in run
    raise ApplicationError(
temporalio.exceptions.ApplicationError: RestrictedWorkflowAccessError: Cannot access urllib.request.urlopen.__call__ from inside a workflow. If this is code from a module not used in a workflow or known to only be used deterministically from a workflow, mark the import as pass through.
WARNING  temporalio.worker.workflow_sandbox._restrictions:_restrictions.py:783 __call__ on http.client.HTTPConnection restricted
DEBUG    temporalio.worker._workflow_instance:_workflow_instance.py:1788 Workflow raised failure with run ID c857f113-ffad-49a7-927a-b6ab81dac61a
Traceback (most recent call last):
  File "/home/runner/work/sdk-python/sdk-python/tests/worker/workflow_sandbox/test_runner.py", line 149, in run
    exec(code)
  File "<string>", line 2, in <module>
  File "/home/runner/work/sdk-python/sdk-python/temporalio/worker/workflow_sandbox/_restrictions.py", line 964, in __call__
    state.assert_child_not_restricted("__call__")
  File "/home/runner/work/sdk-python/sdk-python/temporalio/worker/workflow_sandbox/_restrictions.py", line 792, in assert_child_not_restricted
    raise RestrictedWorkflowAccessError(
temporalio.worker.workflow_sandbox._restrictions.RestrictedWorkflowAccessError: Cannot access http.client.HTTPConnection.__call__ from inside a workflow. If this is code from a module not used in a workflow or known to only be used deterministically from a workflow, mark the import as pass through.

The above exception was the direct cause of the following exception:

Traceback (most recent call last):
  File "/home/runner/work/sdk-python/sdk-python/temporalio/worker/_workflow_instance.py", line 1767, in _run_top_level_workflow_function
    await coro
  File "/home/runner/work/sdk-python/sdk-python/temporalio/worker/_workflow_instance.py", line 831, in run_workflow
    result = await self._inbound.execute_workflow(input)
  File "/home/runner/work/sdk-python/sdk-python/temporalio/testing/_workflow.py", line 493, in execute_workflow
    return await super().execute_workflow(input)
  File "/home/runner/work/sdk-python/sdk-python/temporalio/worker/_interceptor.py", line 328, in execute_workflow
    return await self.next.execute_workflow(input)
  File "/home/runner/work/sdk-python/sdk-python/temporalio/worker/_workflow_instance.py", line 2099, in execute_workflow
    return await input.run_fn(*args)
  File "/home/runner/work/sdk-python/sdk-python/tests/worker/workflow_sandbox/test_runner.py", line 151, in run
    raise ApplicationError(
temporalio.exceptions.ApplicationError: RestrictedWorkflowAccessError: Cannot access http.client.HTTPConnection.__call__ from inside a workflow. If this is code from a module not used in a workflow or known to only be used deterministically from a workflow, mark the import as pass through.
WARNING  temporalio.worker.workflow_sandbox._restrictions:_restrictions.py:783 __call__ on uuid.uuid4 restricted
DEBUG    temporalio.worker._workflow_instance:_workflow_instance.py:1788 Workflow raised failure with run ID 0386a2cf-32b2-4532-b2ea-c796839864b4
Traceback (most recent call last):
  File "/home/runner/work/sdk-python/sdk-python/tests/worker/workflow_sandbox/test_runner.py", line 149, in run
    exec(code)
  File "<string>", line 2, in <module>
  File "/home/runner/work/sdk-python/sdk-python/temporalio/worker/workflow_sandbox/_restrictions.py", line 964, in __call__
    state.assert_child_not_restricted("__call__")
  File "/home/runner/work/sdk-python/sdk-python/temporalio/worker/workflow_sandbox/_restrictions.py", line 792, in assert_child_not_restricted
    raise RestrictedWorkflowAccessError(
temporalio.worker.workflow_sandbox._restrictions.RestrictedWorkflowAccessError: Cannot access uuid.uuid4.__call__ from inside a workflow. If this is code from a module not used in a workflow or known to only be used deterministically from a workflow, mark the import as pass through.

The above exception was the direct cause of the following exception:

Traceback (most recent call last):
  File "/home/runner/work/sdk-python/sdk-python/temporalio/worker/_workflow_instance.py", line 1767, in _run_top_level_workflow_function
    await coro
  File "/home/runner/work/sdk-python/sdk-python/temporalio/worker/_workflow_instance.py", line 831, in run_workflow
    result = await self._inbound.execute_workflow(input)
  File "/home/runner/work/sdk-python/sdk-python/temporalio/testing/_workflow.py", line 493, in execute_workflow
    return await super().execute_workflow(input)
  File "/home/runner/work/sdk-python/sdk-python/temporalio/worker/_interceptor.py", line 328, in execute_workflow
    return await self.next.execute_workflow(input)
  File "/home/runner/work/sdk-python/sdk-python/temporalio/worker/_workflow_instance.py", line 2099, in execute_workflow
    return await input.run_fn(*args)
  File "/home/runner/work/sdk-python/sdk-python/tests/worker/workflow_sandbox/test_runner.py", line 151, in run
    raise ApplicationError(
temporalio.exceptions.ApplicationError: RestrictedWorkflowAccessError: Cannot access uuid.uuid4.__call__ from inside a workflow. If this is code from a module not used in a workflow or known to only be used deterministically from a workflow, mark the import as pass through.
INFO     temporalio.worker._worker:_worker.py:523 Beginning worker shutdown, will wait 0:00:00 before cancelling activities
INFO     temporalio.worker._worker:_worker.py:523 Beginning worker shutdown, will wait 0:00:00 before cancelling activities
WARNING  temporalio.worker.workflow_sandbox._restrictions:_restrictions.py:783 __call__ on datetime.date restricted
DEBUG    temporalio.worker._workflow_instance:_workflow_instance.py:1788 Workflow raised failure with run ID 09baf170-6399-4c9a-86a3-8902f062d013
Traceback (most recent call last):
  File "/home/runner/work/sdk-python/sdk-python/tests/worker/workflow_sandbox/test_runner.py", line 149, in run
    exec(code)
  File "<string>", line 2, in <module>
  File "/home/runner/work/sdk-python/sdk-python/temporalio/worker/workflow_sandbox/_restrictions.py", line 964, in __call__
    state.assert_child_not_restricted("__call__")
  File "/home/runner/work/sdk-python/sdk-python/temporalio/worker/workflow_sandbox/_restrictions.py", line 792, in assert_child_not_restricted
    raise RestrictedWorkflowAccessError(
temporalio.worker.workflow_sandbox._restrictions.RestrictedWorkflowAccessError: Cannot access datetime.date.__call__ from inside a workflow. If this is code from a module not used in a workflow or known to only be used deterministically from a workflow, mark the import as pass through.

The above exception was the direct cause of the following exception:

Traceback (most recent call last):
  File "/home/runner/work/sdk-python/sdk-python/temporalio/worker/_workflow_instance.py", line 1767, in _run_top_level_workflow_function
    await coro
  File "/home/runner/work/sdk-python/sdk-python/temporalio/worker/_workflow_instance.py", line 831, in run_workflow
    result = await self._inbound.execute_workflow(input)
  File "/home/runner/work/sdk-python/sdk-python/temporalio/testing/_workflow.py", line 493, in execute_workflow
    return await super().execute_workflow(input)
  File "/home/runner/work/sdk-python/sdk-python/temporalio/worker/_interceptor.py", line 328, in execute_workflow
    return await self.next.execute_workflow(input)
  File "/home/runner/work/sdk-python/sdk-python/temporalio/worker/_workflow_instance.py", line 2099, in execute_workflow
    return await input.run_fn(*args)
  File "/home/runner/work/sdk-python/sdk-python/tests/worker/workflow_sandbox/test_runner.py", line 151, in run
    raise ApplicationError(
temporalio.exceptions.ApplicationError: RestrictedWorkflowAccessError: Cannot access datetime.date.__call__ from inside a workflow. If this is code from a module not used in a workflow or known to only be used deterministically from a workflow, mark the import as pass through.
INFO     temporalio.worker._worker:_worker.py:523 Beginning worker shutdown, will wait 0:00:00 before cancelling activities