ERROR    asyncio:base_events.py:1820 Task exception was never retrieved
future: <Task finished name='Task-4608' coro=<_UnfinishedHandlersWarningsTest._get_workflow_result() done, defined at /home/runner/work/sdk-python/sdk-python/tests/worker/test_workflow.py:5366> exception=AssertionError("assert (<RPCStatusCode.FAILED_PRECONDITION: 9> == <RPCStatusCode.NOT_FOUND: 5>)\n +  where <RPCStatusCode.FAILED_PRECONDITION: 9> = RPCError('Unable to perform workflow execution update due to Workflow Task in failed state.').status\n +    where RPCError('Unable to perform workflow execution update due to Workflow Task in failed state.') = <ExceptionInfo RPCError('Unable to perform workflow execution update due to Workflow Task in failed state.') tblen=6>.value\n +  and   <RPCStatusCode.NOT_FOUND: 5> = RPCStatusCode.NOT_FOUND")>
Traceback (most recent call last):
  File "/home/runner/work/sdk-python/sdk-python/tests/worker/test_workflow.py", line 5389, in _get_workflow_result
    assert (
AssertionError: assert (<RPCStatusCode.FAILED_PRECONDITION: 9> == <RPCStatusCode.NOT_FOUND: 5>)
 +  where <RPCStatusCode.FAILED_PRECONDITION: 9> = RPCError('Unable to perform workflow execution update due to Workflow Task in failed state.').status
 +    where RPCError('Unable to perform workflow execution update due to Workflow Task in failed state.') = <ExceptionInfo RPCError('Unable to perform workflow execution update due to Workflow Task in failed state.') tblen=6>.value
 +  and   <RPCStatusCode.NOT_FOUND: 5> = RPCStatusCode.NOT_FOUND
DEBUG    temporalio.worker._workflow_instance:_workflow_instance.py:1788 Workflow raised failure with run ID ff85ed70-55f3-4451-98f8-31e72dbf1996
Traceback (most recent call last):
  File "/home/runner/work/sdk-python/sdk-python/temporalio/worker/_workflow_instance.py", line 1767, in _run_top_level_workflow_function
    await coro
  File "/home/runner/work/sdk-python/sdk-python/temporalio/worker/_workflow_instance.py", line 831, in run_workflow
    result = await self._inbound.execute_workflow(input)
             ^^^^^^^^^^^^^^^^^^^^^^^^^^^^^^^^^^^^^^^^^^^
  File "/home/runner/work/sdk-python/sdk-python/temporalio/testing/_workflow.py", line 493, in execute_workflow
    return await super().execute_workflow(input)
           ^^^^^^^^^^^^^^^^^^^^^^^^^^^^^^^^^^^^^
  File "/home/runner/work/sdk-python/sdk-python/temporalio/worker/_interceptor.py", line 328, in execute_workflow
    return await self.next.execute_workflow(input)
           ^^^^^^^^^^^^^^^^^^^^^^^^^^^^^^^^^^^^^^^
  File "/home/runner/work/sdk-python/sdk-python/temporalio/worker/_workflow_instance.py", line 2099, in execute_workflow
    return await input.run_fn(*args)
           ^^^^^^^^^^^^^^^^^^^^^^^^^
  File "/home/runner/work/sdk-python/sdk-python/tests/worker/test_workflow.py", line 5462, in run
    raise ApplicationError(
temporalio.exceptions.ApplicationError: Deliberately failing workflow with an unfinished handler
INFO     temporalio.worker._worker:_worker.py:523 Beginning worker shutdown, will wait 0:00:00 before cancelling activities