DEBUG    temporalio.worker._activity:_activity.py:276 Running activity activity_with_retry_delay (token b'\x00\x07default\x00$2bbbd0a0-701c-478b-b66a-dfcdda51928a\x00$02830939-3199-489f-9568-ac56689c3d1f\x00\x00\x00\x00\x00\x00\x00\x05\x00\x00\x00\x01')
DEBUG    temporalio.activity:_activity.py:440 Starting activity ({'activity_id': '1', 'activity_type': 'activity_with_retry_delay', 'attempt': 1, 'namespace': 'default', 'task_queue': 'a6478046-818d-471a-a2b5-1e6e1458d4fe', 'workflow_id': '2bbbd0a0-701c-478b-b66a-dfcdda51928a', 'workflow_run_id': '02830939-3199-489f-9568-ac56689c3d1f', 'workflow_type': 'ActivitiesWithRetryDelayWorkflow'})
WARNING  temporalio.activity:_activity.py:493 Completing activity as failed ({'activity_id': '1', 'activity_type': 'activity_with_retry_delay', 'attempt': 1, 'namespace': 'default', 'task_queue': 'a6478046-818d-471a-a2b5-1e6e1458d4fe', 'workflow_id': '2bbbd0a0-701c-478b-b66a-dfcdda51928a', 'workflow_run_id': '02830939-3199-489f-9568-ac56689c3d1f', 'workflow_type': 'ActivitiesWithRetryDelayWorkflow'})
Traceback (most recent call last):
  File "/home/runner/work/sdk-python/sdk-python/temporalio/worker/_activity.py", line 453, in _run_activity
    result = await impl.execute_activity(input)
  File "/home/runner/work/sdk-python/sdk-python/temporalio/worker/_activity.py", line 711, in execute_activity
    return await input.fn(*input.args)
  File "/home/runner/work/sdk-python/sdk-python/tests/worker/test_workflow.py", line 5963, in activity_with_retry_delay
    raise ApplicationError(
temporalio.exceptions.ApplicationError: Deliberately failing with next_retry_delay set
DEBUG    temporalio.worker._activity:_activity.py:527 Completing activity with completion: task_token: "\000\007default\000$2bbbd0a0-701c-478b-b66a-dfcdda51928a\000$02830939-3199-489f-9568-ac56689c3d1f\000\000\000\000\000\000\000\005\000\000\000\001"
result {
  failed {
    failure {
      message: "Deliberately failing with next_retry_delay set"
      stack_trace: "  File \"/home/runner/work/sdk-python/sdk-python/temporalio/worker/_activity.py\", line 453, in _run_activity\n    result = await impl.execute_activity(input)\n\n  File \"/home/runner/work/sdk-python/sdk-python/temporalio/worker/_activity.py\", line 711, in execute_activity\n    return await input.fn(*input.args)\n\n  File \"/home/runner/work/sdk-python/sdk-python/tests/worker/test_workflow.py\", line 5963, in activity_with_retry_delay\n    raise ApplicationError(\n"
      application_failure_info {
        next_retry_delay {
          nanos: 5000000
        }
      }
    }
  }
}

DEBUG    temporalio.worker._activity:_activity.py:276 Running activity activity_with_retry_delay (token b'\x00\x07default\x00$2bbbd0a0-701c-478b-b66a-dfcdda51928a\x00$02830939-3199-489f-9568-ac56689c3d1f\x00\x00\x00\x00\x00\x00\x00\x05\x00\x00\x00\x02')
DEBUG    temporalio.activity:_activity.py:440 Starting activity ({'activity_id': '1', 'activity_type': 'activity_with_retry_delay', 'attempt': 2, 'namespace': 'default', 'task_queue': 'a6478046-818d-471a-a2b5-1e6e1458d4fe', 'workflow_id': '2bbbd0a0-701c-478b-b66a-dfcdda51928a', 'workflow_run_id': '02830939-3199-489f-9568-ac56689c3d1f', 'workflow_type': 'ActivitiesWithRetryDelayWorkflow'})
WARNING  temporalio.activity:_activity.py:493 Completing activity as failed ({'activity_id': '1', 'activity_type': 'activity_with_retry_delay', 'attempt': 2, 'namespace': 'default', 'task_queue': 'a6478046-818d-471a-a2b5-1e6e1458d4fe', 'workflow_id': '2bbbd0a0-701c-478b-b66a-dfcdda51928a', 'workflow_run_id': '02830939-3199-489f-9568-ac56689c3d1f', 'workflow_type': 'ActivitiesWithRetryDelayWorkflow'})
Traceback (most recent call last):
  File "/home/runner/work/sdk-python/sdk-python/temporalio/worker/_activity.py", line 453, in _run_activity
    result = await impl.execute_activity(input)
  File "/home/runner/work/sdk-python/sdk-python/temporalio/worker/_activity.py", line 711, in execute_activity
    return await input.fn(*input.args)
  File "/home/runner/work/sdk-python/sdk-python/tests/worker/test_workflow.py", line 5963, in activity_with_retry_delay
    raise ApplicationError(
temporalio.exceptions.ApplicationError: Deliberately failing with next_retry_delay set
DEBUG    temporalio.worker._activity:_activity.py:527 Completing activity with completion: task_token: "\000\007default\000$2bbbd0a0-701c-478b-b66a-dfcdda51928a\000$02830939-3199-489f-9568-ac56689c3d1f\000\000\000\000\000\000\000\005\000\000\000\002"
result {
  failed {
    failure {
      message: "Deliberately failing with next_retry_delay set"
      stack_trace: "  File \"/home/runner/work/sdk-python/sdk-python/temporalio/worker/_activity.py\", line 453, in _run_activity\n    result = await impl.execute_activity(input)\n\n  File \"/home/runner/work/sdk-python/sdk-python/temporalio/worker/_activity.py\", line 711, in execute_activity\n    return await input.fn(*input.args)\n\n  File \"/home/runner/work/sdk-python/sdk-python/tests/worker/test_workflow.py\", line 5963, in activity_with_retry_delay\n    raise ApplicationError(\n"
      application_failure_info {
        next_retry_delay {
          nanos: 5000000
        }
      }
    }
  }
}

DEBUG    temporalio.worker._workflow_instance:_workflow_instance.py:1788 Workflow raised failure with run ID 02830939-3199-489f-9568-ac56689c3d1f
temporalio.exceptions.ApplicationError: Deliberately failing with next_retry_delay set

The above exception was the direct cause of the following exception:

Traceback (most recent call last):
  File "/home/runner/work/sdk-python/sdk-python/temporalio/worker/_workflow_instance.py", line 1767, in _run_top_level_workflow_function
    await coro
  File "/home/runner/work/sdk-python/sdk-python/temporalio/worker/_workflow_instance.py", line 831, in run_workflow
    result = await self._inbound.execute_workflow(input)
  File "/home/runner/work/sdk-python/sdk-python/temporalio/testing/_workflow.py", line 493, in execute_workflow
    return await super().execute_workflow(input)
  File "/home/runner/work/sdk-python/sdk-python/temporalio/worker/_interceptor.py", line 328, in execute_workflow
    return await self.next.execute_workflow(input)
  File "/home/runner/work/sdk-python/sdk-python/temporalio/worker/_workflow_instance.py", line 2099, in execute_workflow
    return await input.run_fn(*args)
  File "/home/runner/work/sdk-python/sdk-python/tests/worker/test_workflow.py", line 5976, in run
    await workflow.execute_activity(
  File "/home/runner/work/sdk-python/sdk-python/temporalio/workflow.py", line 2011, in execute_activity
    return await _Runtime.current().workflow_start_activity(
  File "/home/runner/work/sdk-python/sdk-python/temporalio/worker/_workflow_instance.py", line 1423, in run_activity
    return await asyncio.shield(handle._result_fut)
temporalio.exceptions.ActivityError: Activity task failed
INFO     temporalio.worker._worker:_worker.py:523 Beginning worker shutdown, will wait 0:00:00 before cancelling activities