DEBUG    temporalio.worker._activity:_activity.py:276 Running activity wrong_activity (token b'\x00\x07default\x00$e16c758c-8511-4926-ad05-41b69bcb1d81\x00$e2649a4c-7da0-41d3-96e0-b3640fcc294a\x00\x00\x00\x00\x00\x00\x00\x05\x00\x00\x00\x01')
WARNING  temporalio.activity:_activity.py:493 Completing activity as failed
Traceback (most recent call last):
  File "/home/runner/work/sdk-python/sdk-python/temporalio/worker/_activity.py", line 290, in _run_activity
    raise temporalio.exceptions.ApplicationError(
temporalio.exceptions.ApplicationError: NotFoundError: Activity function wrong_activity for workflow e16c758c-8511-4926-ad05-41b69bcb1d81 is not registered on this worker, available activities: say_hello
DEBUG    temporalio.worker._activity:_activity.py:527 Completing activity with completion: task_token: "\000\007default\000$e16c758c-8511-4926-ad05-41b69bcb1d81\000$e2649a4c-7da0-41d3-96e0-b3640fcc294a\000\000\000\000\000\000\000\005\000\000\000\001"
result {
  failed {
    failure {
      message: "Activity function wrong_activity for workflow e16c758c-8511-4926-ad05-41b69bcb1d81 is not registered on this worker, available activities: say_hello"
      stack_trace: "  File \"/home/runner/work/sdk-python/sdk-python/temporalio/worker/_activity.py\", line 290, in _run_activity\n    raise temporalio.exceptions.ApplicationError(\n"
      application_failure_info {
        type: "NotFoundError"
      }
    }
  }
}

DEBUG    temporalio.worker._workflow_instance:_workflow_instance.py:1788 Workflow raised failure with run ID e2649a4c-7da0-41d3-96e0-b3640fcc294a
temporalio.exceptions.ApplicationError: NotFoundError: Activity function wrong_activity for workflow e16c758c-8511-4926-ad05-41b69bcb1d81 is not registered on this worker, available activities: say_hello

The above exception was the direct cause of the following exception:

Traceback (most recent call last):
  File "/home/runner/work/sdk-python/sdk-python/temporalio/worker/_workflow_instance.py", line 1767, in _run_top_level_workflow_function
    await coro
  File "/home/runner/work/sdk-python/sdk-python/temporalio/worker/_workflow_instance.py", line 831, in run_workflow
    result = await self._inbound.execute_workflow(input)
  File "/home/runner/work/sdk-python/sdk-python/temporalio/testing/_workflow.py", line 493, in execute_workflow
    return await super().execute_workflow(input)
  File "/home/runner/work/sdk-python/sdk-python/temporalio/worker/_interceptor.py", line 328, in execute_workflow
    return await self.next.execute_workflow(input)
  File "/home/runner/work/sdk-python/sdk-python/temporalio/worker/_workflow_instance.py", line 2099, in execute_workflow
    return await input.run_fn(*args)
  File "/home/runner/work/sdk-python/sdk-python/tests/helpers/worker.py", line 97, in run
    should_return, ret = await self.handle_action(params, action)
  File "/home/runner/work/sdk-python/sdk-python/tests/helpers/worker.py", line 204, in handle_action
    raise task.exception()  # type: ignore
  File "/home/runner/work/sdk-python/sdk-python/tests/helpers/worker.py", line 193, in run_activity
    last_result = await task
  File "/home/runner/work/sdk-python/sdk-python/temporalio/worker/_workflow_instance.py", line 1423, in run_activity
    return await asyncio.shield(handle._result_fut)
temporalio.exceptions.ActivityError: Activity task failed
INFO     temporalio.worker._worker:_worker.py:523 Beginning worker shutdown, will wait 0:00:00 before cancelling activities