DEBUG    temporalio.worker._activity:_activity.py:276 Running activity say_hello (token b'\x00\x07default\x00-workflow-239aa862-35d0-4a49-a481-59843ce38f84\x00$f8f2c099-9c61-431c-99dd-d5747b1d67db\x00\x00\x00\x00\x00\x00\x00\x05\x00\x00\x00\x01')
DEBUG    temporalio.activity:_activity.py:440 Starting activity ({'activity_id': '1', 'activity_type': 'say_hello', 'attempt': 1, 'namespace': 'default', 'task_queue': '77b40f0b-5da0-4d55-b1b1-f8336e7175f0', 'workflow_id': 'workflow-239aa862-35d0-4a49-a481-59843ce38f84', 'workflow_run_id': 'f8f2c099-9c61-431c-99dd-d5747b1d67db', 'workflow_type': 'SayHelloWorkflow'})
DEBUG    temporalio.worker._activity:_activity.py:527 Completing activity with completion: task_token: "\000\007default\000-workflow-239aa862-35d0-4a49-a481-59843ce38f84\000$f8f2c099-9c61-431c-99dd-d5747b1d67db\000\000\000\000\000\000\000\005\000\000\000\001"
result {
  completed {
    result {
      metadata {
        key: "encoding"
        value: "json/plain"
      }
      data: "\"Hello, Temporal!\""
    }
  }
}

DEBUG    temporalio.worker._workflow_instance:_workflow_instance.py:1788 Workflow raised failure with run ID f8f2c099-9c61-431c-99dd-d5747b1d67db
Traceback (most recent call last):
  File "/home/runner/work/sdk-python/sdk-python/temporalio/worker/_workflow_instance.py", line 1767, in _run_top_level_workflow_function
    await coro
  File "/home/runner/work/sdk-python/sdk-python/temporalio/worker/_workflow_instance.py", line 831, in run_workflow
    result = await self._inbound.execute_workflow(input)
  File "/home/runner/work/sdk-python/sdk-python/temporalio/testing/_workflow.py", line 493, in execute_workflow
    return await super().execute_workflow(input)
  File "/home/runner/work/sdk-python/sdk-python/temporalio/worker/_interceptor.py", line 328, in execute_workflow
    return await self.next.execute_workflow(input)
  File "/home/runner/work/sdk-python/sdk-python/temporalio/worker/_workflow_instance.py", line 2099, in execute_workflow
    return await input.run_fn(*args)
  File "/home/runner/work/sdk-python/sdk-python/tests/worker/test_replayer.py", line 52, in run
    raise ApplicationError("Intentional error")
temporalio.exceptions.ApplicationError: Intentional error
INFO     temporalio.worker._worker:_worker.py:523 Beginning worker shutdown, will wait 0:00:00 before cancelling activities
DEBUG    temporalio.worker._workflow_instance:_workflow_instance.py:1788 Workflow raised failure with run ID f8f2c099-9c61-431c-99dd-d5747b1d67db
Traceback (most recent call last):
  File "/home/runner/work/sdk-python/sdk-python/temporalio/worker/_workflow_instance.py", line 1767, in _run_top_level_workflow_function
    await coro
  File "/home/runner/work/sdk-python/sdk-python/temporalio/worker/_workflow_instance.py", line 831, in run_workflow
    result = await self._inbound.execute_workflow(input)
  File "/home/runner/work/sdk-python/sdk-python/temporalio/worker/_workflow_instance.py", line 2099, in execute_workflow
    return await input.run_fn(*args)
  File "/home/runner/work/sdk-python/sdk-python/tests/worker/test_replayer.py", line 52, in run
    raise ApplicationError("Intentional error")
temporalio.exceptions.ApplicationError: Intentional error
DEBUG    temporalio.worker._workflow:_workflow.py:299 Evicting workflow with run ID f8f2c099-9c61-431c-99dd-d5747b1d67db, message: Always evict workflows after replay