DEBUG    temporalio.worker._activity:_activity.py:276 Running activity picklable_activity_failure (token b'\n$8aa290fa-b00f-4fa1-a139-85696fcc157a\x12$e0ddeec7-65a8-4edb-8a51-dbd353dc23a4\x1a$f9363624-54ca-4667-b986-1d41c719c3d1 \x05(\x012\x011B\x1apicklable_activity_failureJ\x08\x08\x01\x10\x91\x8c@\x18\x01')
DEBUG    temporalio.activity:_activity.py:440 Starting activity ({'activity_id': '1', 'activity_type': 'picklable_activity_failure', 'attempt': 1, 'namespace': 'default', 'task_queue': '2530b208-8733-4052-8593-9c1d4ca3231a', 'workflow_id': 'e0ddeec7-65a8-4edb-8a51-dbd353dc23a4', 'workflow_run_id': 'f9363624-54ca-4667-b986-1d41c719c3d1', 'workflow_type': 'kitchen_sink'})
WARNING  temporalio.activity:_activity.py:493 Completing activity as failed ({'activity_id': '1', 'activity_type': 'picklable_activity_failure', 'attempt': 1, 'namespace': 'default', 'task_queue': '2530b208-8733-4052-8593-9c1d4ca3231a', 'workflow_id': 'e0ddeec7-65a8-4edb-8a51-dbd353dc23a4', 'workflow_run_id': 'f9363624-54ca-4667-b986-1d41c719c3d1', 'workflow_type': 'kitchen_sink'})
concurrent.futures.process._RemoteTraceback: 
"""
Traceback (most recent call last):
  File "/opt/hostedtoolcache/Python/3.8.18/arm64/lib/python3.8/concurrent/futures/process.py", line 239, in _process_worker
    r = call_item.fn(*call_item.args, **call_item.kwargs)
  File "/home/runner/work/sdk-python/sdk-python/temporalio/worker/_activity.py", line 774, in _execute_sync_activity
    return fn(*args)
  File "/home/runner/work/sdk-python/sdk-python/tests/worker/test_activity.py", line 214, in picklable_activity_failure
    raise RuntimeError("oh no!")
RuntimeError: oh no!
"""

The above exception was the direct cause of the following exception:

Traceback (most recent call last):
  File "/home/runner/work/sdk-python/sdk-python/temporalio/worker/_activity.py", line 453, in _run_activity
    result = await impl.execute_activity(input)
  File "/home/runner/work/sdk-python/sdk-python/temporalio/worker/_activity.py", line 705, in execute_activity
    return await loop.run_in_executor(input.executor, func, *args)
RuntimeError: oh no!
DEBUG    temporalio.worker._activity:_activity.py:527 Completing activity with completion: task_token: "\n$8aa290fa-b00f-4fa1-a139-85696fcc157a\022$e0ddeec7-65a8-4edb-8a51-dbd353dc23a4\032$f9363624-54ca-4667-b986-1d41c719c3d1 \005(\0012\0011B\032picklable_activity_failureJ\010\010\001\020\221\214@\030\001"
result {
  failed {
    failure {
      message: "oh no!"
      stack_trace: "  File \"/home/runner/work/sdk-python/sdk-python/temporalio/worker/_activity.py\", line 453, in _run_activity\n    result = await impl.execute_activity(input)\n\n  File \"/home/runner/work/sdk-python/sdk-python/temporalio/worker/_activity.py\", line 705, in execute_activity\n    return await loop.run_in_executor(input.executor, func, *args)\n"
      cause {
        message: "\n\"\"\"\nTraceback (most recent call last):\n  File \"/opt/hostedtoolcache/Python/3.8.18/arm64/lib/python3.8/concurrent/futures/process.py\", line 239, in _process_worker\n    r = call_item.fn(*call_item.args, **call_item.kwargs)\n  File \"/home/runner/work/sdk-python/sdk-python/temporalio/worker/_activity.py\", line 774, in _execute_sync_activity\n    return fn(*args)\n  File \"/home/runner/work/sdk-python/sdk-python/tests/worker/test_activity.py\", line 214, in picklable_activity_failure\n    raise RuntimeError(\"oh no!\")\nRuntimeError: oh no!\n\"\"\""
        application_failure_info {
          type: "_RemoteTraceback"
        }
      }
      application_failure_info {
        type: "RuntimeError"
      }
    }
  }
}

DEBUG    temporalio.worker._workflow_instance:_workflow_instance.py:1788 Workflow raised failure with run ID f9363624-54ca-4667-b986-1d41c719c3d1
temporalio.exceptions.ApplicationError: _RemoteTraceback: 
"""
Traceback (most recent call last):
  File "/opt/hostedtoolcache/Python/3.8.18/arm64/lib/python3.8/concurrent/futures/process.py", line 239, in _process_worker
    r = call_item.fn(*call_item.args, **call_item.kwargs)
  File "/home/runner/work/sdk-python/sdk-python/temporalio/worker/_activity.py", line 774, in _execute_sync_activity
    return fn(*args)
  File "/home/runner/work/sdk-python/sdk-python/tests/worker/test_activity.py", line 214, in picklable_activity_failure
    raise RuntimeError("oh no!")
RuntimeError: oh no!
"""

The above exception was the direct cause of the following exception:

temporalio.exceptions.ApplicationError: RuntimeError: oh no!

The above exception was the direct cause of the following exception:

Traceback (most recent call last):
  File "/home/runner/work/sdk-python/sdk-python/temporalio/worker/_workflow_instance.py", line 1767, in _run_top_level_workflow_function
    await coro
  File "/home/runner/work/sdk-python/sdk-python/temporalio/worker/_workflow_instance.py", line 831, in run_workflow
    result = await self._inbound.execute_workflow(input)
  File "/home/runner/work/sdk-python/sdk-python/temporalio/testing/_workflow.py", line 493, in execute_workflow
    return await super().execute_workflow(input)
  File "/home/runner/work/sdk-python/sdk-python/temporalio/worker/_interceptor.py", line 328, in execute_workflow
    return await self.next.execute_workflow(input)
  File "/home/runner/work/sdk-python/sdk-python/temporalio/worker/_workflow_instance.py", line 2099, in execute_workflow
    return await input.run_fn(*args)
  File "/home/runner/work/sdk-python/sdk-python/tests/helpers/worker.py", line 97, in run
    should_return, ret = await self.handle_action(params, action)
  File "/home/runner/work/sdk-python/sdk-python/tests/helpers/worker.py", line 204, in handle_action
    raise task.exception()  # type: ignore
  File "/home/runner/work/sdk-python/sdk-python/tests/helpers/worker.py", line 193, in run_activity
    last_result = await task
  File "/home/runner/work/sdk-python/sdk-python/temporalio/worker/_workflow_instance.py", line 1423, in run_activity
    return await asyncio.shield(handle._result_fut)
temporalio.exceptions.ActivityError: Activity task failed
INFO     temporalio.worker._worker:_worker.py:523 Beginning worker shutdown, will wait 0:00:00 before cancelling activities