DEBUG    temporalio.worker._activity:_activity.py:276 Running activity custom_error_activity (token b'\x00\x07default\x00-workflow-631542a2-4db1-4156-a33a-fd5e7b7c07b9\x00$8c9a42a1-9f6d-4ec7-82b0-ddca60ad4d9c\x00\x00\x00\x00\x00\x00\x00\x05\x00\x00\x00\x01')
DEBUG    temporalio.activity:_activity.py:440 Starting activity ({'activity_id': '1', 'activity_type': 'custom_error_activity', 'attempt': 1, 'namespace': 'default', 'task_queue': 'c240c899-c4db-42e3-bb17-7e02177db818', 'workflow_id': 'workflow-631542a2-4db1-4156-a33a-fd5e7b7c07b9', 'workflow_run_id': '8c9a42a1-9f6d-4ec7-82b0-ddca60ad4d9c', 'workflow_type': 'CustomErrorWorkflow'})
WARNING  temporalio.activity:_activity.py:493 Completing activity as failed ({'activity_id': '1', 'activity_type': 'custom_error_activity', 'attempt': 1, 'namespace': 'default', 'task_queue': 'c240c899-c4db-42e3-bb17-7e02177db818', 'workflow_id': 'workflow-631542a2-4db1-4156-a33a-fd5e7b7c07b9', 'workflow_run_id': '8c9a42a1-9f6d-4ec7-82b0-ddca60ad4d9c', 'workflow_type': 'CustomErrorWorkflow'})
Traceback (most recent call last):
  File "/home/runner/work/sdk-python/sdk-python/temporalio/worker/_activity.py", line 453, in _run_activity
    result = await impl.execute_activity(input)
  File "/home/runner/work/sdk-python/sdk-python/temporalio/worker/_activity.py", line 711, in execute_activity
    return await input.fn(*input.args)
  File "/home/runner/work/sdk-python/sdk-python/tests/worker/test_workflow.py", line 3228, in custom_error_activity
    raise MyCustomError("activity error!")
tests.worker.test_workflow.MyCustomError: MyCustomError: activity error!
DEBUG    temporalio.worker._activity:_activity.py:527 Completing activity with completion: task_token: "\000\007default\000-workflow-631542a2-4db1-4156-a33a-fd5e7b7c07b9\000$8c9a42a1-9f6d-4ec7-82b0-ddca60ad4d9c\000\000\000\000\000\000\000\005\000\000\000\001"
result {
  failed {
    failure {
      message: "Encoded failure"
      encoded_attributes {
        metadata {
          key: "encoding"
          value: "json/plain"
        }
        data: "{\"message\":\"activity error!\",\"stack_trace\":\"  File \\\"/home/runner/work/sdk-python/sdk-python/temporalio/worker/_activity.py\\\", line 453, in _run_activity\\n    result = await impl.execute_activity(input)\\n\\n  File \\\"/home/runner/work/sdk-python/sdk-python/temporalio/worker/_activity.py\\\", line 711, in execute_activity\\n    return await input.fn(*input.args)\\n\\n  File \\\"/home/runner/work/sdk-python/sdk-python/tests/worker/test_workflow.py\\\", line 3228, in custom_error_activity\\n    raise MyCustomError(\\\"activity error!\\\")\\n\"}"
      }
      application_failure_info {
        type: "MyCustomError"
        non_retryable: true
      }
    }
  }
}

DEBUG    temporalio.worker._workflow_instance:_workflow_instance.py:1788 Workflow raised failure with run ID 8c9a42a1-9f6d-4ec7-82b0-ddca60ad4d9c
tests.worker.test_workflow.MyCustomError: MyCustomError: activity error!

The above exception was the direct cause of the following exception:

Traceback (most recent call last):
  File "/home/runner/work/sdk-python/sdk-python/tests/worker/test_workflow.py", line 3236, in run
    await workflow.execute_activity(
  File "/home/runner/work/sdk-python/sdk-python/temporalio/workflow.py", line 2011, in execute_activity
    return await _Runtime.current().workflow_start_activity(
  File "/home/runner/work/sdk-python/sdk-python/temporalio/worker/_workflow_instance.py", line 1423, in run_activity
    return await asyncio.shield(handle._result_fut)
temporalio.exceptions.ActivityError: Activity task failed

During handling of the above exception, another exception occurred:

Traceback (most recent call last):
  File "/home/runner/work/sdk-python/sdk-python/temporalio/worker/_workflow_instance.py", line 1767, in _run_top_level_workflow_function
    await coro
  File "/home/runner/work/sdk-python/sdk-python/temporalio/worker/_workflow_instance.py", line 831, in run_workflow
    result = await self._inbound.execute_workflow(input)
  File "/home/runner/work/sdk-python/sdk-python/temporalio/testing/_workflow.py", line 493, in execute_workflow
    return await super().execute_workflow(input)
  File "/home/runner/work/sdk-python/sdk-python/temporalio/worker/_interceptor.py", line 328, in execute_workflow
    return await self.next.execute_workflow(input)
  File "/home/runner/work/sdk-python/sdk-python/temporalio/worker/_workflow_instance.py", line 2099, in execute_workflow
    return await input.run_fn(*args)
  File "/home/runner/work/sdk-python/sdk-python/tests/worker/test_workflow.py", line 3240, in run
    raise MyCustomError("workflow error!")
tests.worker.test_workflow.MyCustomError: MyCustomError: workflow error!
INFO     temporalio.worker._worker:_worker.py:523 Beginning worker shutdown, will wait 0:00:00 before cancelling activities