DEBUG    temporalio.worker._activity:_activity.py:276 Running activity raise_error (token b'\n$e6d2a310-ce30-4dfe-87db-9ed829a8df47\x12$e5dd3d96-6fe2-444b-a254-9908f1852c9c\x1a$2974a8ad-48e7-4fe8-a98c-4fb3054bb00f \x05(\x012\x011B\x0braise_errorJ\x08\x08\x01\x10\xe5\x8b@\x18\x01')
DEBUG    temporalio.activity:_activity.py:440 Starting activity ({'activity_id': '1', 'activity_type': 'raise_error', 'attempt': 1, 'namespace': 'default', 'task_queue': '99f7188b-2f4f-4a27-9753-c467ad148fa5', 'workflow_id': 'e5dd3d96-6fe2-444b-a254-9908f1852c9c', 'workflow_run_id': '2974a8ad-48e7-4fe8-a98c-4fb3054bb00f', 'workflow_type': 'kitchen_sink'})
WARNING  temporalio.activity:_activity.py:493 Completing activity as failed ({'activity_id': '1', 'activity_type': 'raise_error', 'attempt': 1, 'namespace': 'default', 'task_queue': '99f7188b-2f4f-4a27-9753-c467ad148fa5', 'workflow_id': 'e5dd3d96-6fe2-444b-a254-9908f1852c9c', 'workflow_run_id': '2974a8ad-48e7-4fe8-a98c-4fb3054bb00f', 'workflow_type': 'kitchen_sink'})
Traceback (most recent call last):
  File "/home/runner/work/sdk-python/sdk-python/temporalio/worker/_activity.py", line 453, in _run_activity
    result = await impl.execute_activity(input)
             ^^^^^^^^^^^^^^^^^^^^^^^^^^^^^^^^^^
  File "/home/runner/work/sdk-python/sdk-python/temporalio/worker/_activity.py", line 711, in execute_activity
    return await input.fn(*input.args)
           ^^^^^^^^^^^^^^^^^^^^^^^^^^^
  File "/home/runner/work/sdk-python/sdk-python/tests/worker/test_activity.py", line 205, in raise_error
    raise RuntimeError("oh no!")
RuntimeError: oh no!
DEBUG    temporalio.worker._activity:_activity.py:527 Completing activity with completion: task_token: "\n$e6d2a310-ce30-4dfe-87db-9ed829a8df47\022$e5dd3d96-6fe2-444b-a254-9908f1852c9c\032$2974a8ad-48e7-4fe8-a98c-4fb3054bb00f \005(\0012\0011B\013raise_errorJ\010\010\001\020\345\213@\030\001"
result {
  failed {
    failure {
      message: "oh no!"
      stack_trace: "  File \"/home/runner/work/sdk-python/sdk-python/temporalio/worker/_activity.py\", line 453, in _run_activity\n    result = await impl.execute_activity(input)\n             ^^^^^^^^^^^^^^^^^^^^^^^^^^^^^^^^^^\n\n  File \"/home/runner/work/sdk-python/sdk-python/temporalio/worker/_activity.py\", line 711, in execute_activity\n    return await input.fn(*input.args)\n           ^^^^^^^^^^^^^^^^^^^^^^^^^^^\n\n  File \"/home/runner/work/sdk-python/sdk-python/tests/worker/test_activity.py\", line 205, in raise_error\n    raise RuntimeError(\"oh no!\")\n"
      application_failure_info {
        type: "RuntimeError"
      }
    }
  }
}

DEBUG    temporalio.worker._workflow_instance:_workflow_instance.py:1788 Workflow raised failure with run ID 2974a8ad-48e7-4fe8-a98c-4fb3054bb00f
temporalio.exceptions.ApplicationError: RuntimeError: oh no!

The above exception was the direct cause of the following exception:

Traceback (most recent call last):
  File "/home/runner/work/sdk-python/sdk-python/temporalio/worker/_workflow_instance.py", line 1767, in _run_top_level_workflow_function
    await coro
  File "/home/runner/work/sdk-python/sdk-python/temporalio/worker/_workflow_instance.py", line 831, in run_workflow
    result = await self._inbound.execute_workflow(input)
             ^^^^^^^^^^^^^^^^^^^^^^^^^^^^^^^^^^^^^^^^^^^
  File "/home/runner/work/sdk-python/sdk-python/temporalio/testing/_workflow.py", line 493, in execute_workflow
    return await super().execute_workflow(input)
           ^^^^^^^^^^^^^^^^^^^^^^^^^^^^^^^^^^^^^
  File "/home/runner/work/sdk-python/sdk-python/temporalio/worker/_interceptor.py", line 328, in execute_workflow
    return await self.next.execute_workflow(input)
           ^^^^^^^^^^^^^^^^^^^^^^^^^^^^^^^^^^^^^^^
  File "/home/runner/work/sdk-python/sdk-python/temporalio/worker/_workflow_instance.py", line 2099, in execute_workflow
    return await input.run_fn(*args)
           ^^^^^^^^^^^^^^^^^^^^^^^^^
  File "/home/runner/work/sdk-python/sdk-python/tests/helpers/worker.py", line 97, in run
    should_return, ret = await self.handle_action(params, action)
                         ^^^^^^^^^^^^^^^^^^^^^^^^^^^^^^^^^^^^^^^^
  File "/home/runner/work/sdk-python/sdk-python/tests/helpers/worker.py", line 204, in handle_action
    raise task.exception()  # type: ignore
    ^^^^^^^^^^^^^^^^^^^^^^
  File "/home/runner/work/sdk-python/sdk-python/tests/helpers/worker.py", line 193, in run_activity
    last_result = await task
                  ^^^^^^^^^^
  File "/home/runner/work/sdk-python/sdk-python/temporalio/worker/_workflow_instance.py", line 1423, in run_activity
    return await asyncio.shield(handle._result_fut)
           ^^^^^^^^^^^^^^^^^^^^^^^^^^^^^^^^^^^^^^^^
temporalio.exceptions.ActivityError: Activity task failed
INFO     temporalio.worker._worker:_worker.py:523 Beginning worker shutdown, will wait 0:00:00 before cancelling activities