DEBUG    temporalio.worker._workflow_instance:_workflow_instance.py:1788 Workflow raised failure with run ID d4c1a1d1-aa1a-4d43-b899-f30781bb1588
Traceback (most recent call last):
  File "/home/runner/work/sdk-python/sdk-python/temporalio/worker/_workflow_instance.py", line 1767, in _run_top_level_workflow_function
    await coro
  File "/home/runner/work/sdk-python/sdk-python/temporalio/worker/_workflow_instance.py", line 831, in run_workflow
    result = await self._inbound.execute_workflow(input)
  File "/home/runner/work/sdk-python/sdk-python/temporalio/worker/_workflow_instance.py", line 2099, in execute_workflow
    return await input.run_fn(*args)
  File "/home/runner/work/sdk-python/sdk-python/tests/test_runtime.py", line 139, in run
    raise RuntimeError("Intentional error")
RuntimeError: Intentional error
WARNING  temporalio.worker._workflow_instance:_workflow_instance.py:385 Failed activation on workflow TaskFailWorkflow with ID workflow-e1bc361e-4c8b-46e0-9514-ae165d8ae93c and run ID d4c1a1d1-aa1a-4d43-b899-f30781bb1588
Traceback (most recent call last):
  File "/home/runner/work/sdk-python/sdk-python/temporalio/worker/_workflow_instance.py", line 351, in activate
    self._run_once(check_conditions=index == 1 or index == 2)
  File "/home/runner/work/sdk-python/sdk-python/temporalio/worker/_workflow_instance.py", line 1749, in _run_once
    raise self._current_activation_error
  File "/home/runner/work/sdk-python/sdk-python/temporalio/worker/_workflow_instance.py", line 1767, in _run_top_level_workflow_function
    await coro
  File "/home/runner/work/sdk-python/sdk-python/temporalio/worker/_workflow_instance.py", line 831, in run_workflow
    result = await self._inbound.execute_workflow(input)
  File "/home/runner/work/sdk-python/sdk-python/temporalio/worker/_workflow_instance.py", line 2099, in execute_workflow
    return await input.run_fn(*args)
  File "/home/runner/work/sdk-python/sdk-python/tests/test_runtime.py", line 139, in run
    raise RuntimeError("Intentional error")
RuntimeError: Intentional error
DEBUG    temporalio.worker._workflow:_workflow.py:299 Evicting workflow with run ID d4c1a1d1-aa1a-4d43-b899-f30781bb1588, message: Workflow activation completion failed: Failure { failure: Some(Failure { message: "Intentional error", source: "", stack_trace: "  File \"/home/runner/work/sdk-python/sdk-python/temporalio/worker/_workflow_instance.py\", line 351, in activate\n    self._run_once(check_conditions=index == 1 or index == 2)\n\n  File \"/home/runner/work/sdk-python/sdk-python/temporalio/worker/_workflow_instance.py\", line 1749, in _run_once\n    raise self._current_activation_error\n\n  File \"/home/runner/work/sdk-python/sdk-python/temporalio/worker/_workflow_instance.py\", line 1767, in _run_top_level_workflow_function\n    await coro\n\n  File \"/home/runner/work/sdk-python/sdk-python/temporalio/worker/_workflow_instance.py\", line 831, in run_workflow\n    result = await self._inbound.execute_workflow(input)\n\n  File \"/home/runner/work/sdk-python/sdk-python/temporalio/worker/_workflow_instance.py\", line 2099, in execute_workflow\n    return await input.run_fn(*args)\n\n  File \"/home/runner/work/sdk-python/sdk-python/tests/test_runtime.py\", line 139, in run\n    raise RuntimeError(\"Intentional error\")\n", encoded_attributes: None, cause: None, failure_info: Some(ApplicationFailureInfo(ApplicationFailureInfo { r#type: "RuntimeError", non_retryable: false, details: None, next_retry_delay: None })) }), force_cause: Unspecified }
WARNING  log-34115b8a-b518-4a45-9a3d-b011d4d49ff8-sdk_core::temporal_sdk_core::worker::workflow:(sdk-core):0 [sdk_core::temporal_sdk_core::worker::workflow] Failing workflow task {'run_id': 'd4c1a1d1-aa1a-4d43-b899-f30781bb1588', 'failure': 'Failure { failure: Some(Failure { message: "Intentional error", source: "", stack_trace: "  File \\"/home/runner/work/sdk-python/sdk-python/temporalio/worker/_workflow_instance.py\\", line 351, in activate\\n    self._run_once(check_conditions=index == 1 or index == 2)\\n\\n  File \\"/home/runner/work/sdk-python/sdk-python/temporalio/worker/_workflow_instance.py\\", line 1749, in _run_once\\n    raise self._current_activation_error\\n\\n  File \\"/home/runner/work/sdk-python/sdk-python/temporalio/worker/_workflow_instance.py\\", line 1767, in _run_top_level_workflow_function\\n    await coro\\n\\n  File \\"/home/runner/work/sdk-python/sdk-python/temporalio/worker/_workflow_instance.py\\", line 831, in run_workflow\\n    result = await self._inbound.execute_workflow(input)\\n\\n  File \\"/home/runner/work/sdk-python/sdk-python/temporalio/worker/_workflow_instance.py\\", line 2099, in execute_workflow\\n    return await input.run_fn(*args)\\n\\n  File \\"/home/runner/work/sdk-python/sdk-python/tests/test_runtime.py\\", line 139, in run\\n    raise RuntimeError(\\"Intentional error\\")\\n", encoded_attributes: None, cause: None, failure_info: Some(ApplicationFailureInfo(ApplicationFailureInfo { r#type: "RuntimeError", non_retryable: false, details: None, next_retry_delay: None })) }), force_cause: Unspecified }'}
DEBUG    temporalio.worker._workflow_instance:_workflow_instance.py:1788 Workflow raised failure with run ID d4c1a1d1-aa1a-4d43-b899-f30781bb1588
Traceback (most recent call last):
  File "/home/runner/work/sdk-python/sdk-python/temporalio/worker/_workflow_instance.py", line 1767, in _run_top_level_workflow_function
    await coro
  File "/home/runner/work/sdk-python/sdk-python/temporalio/worker/_workflow_instance.py", line 831, in run_workflow
    result = await self._inbound.execute_workflow(input)
  File "/home/runner/work/sdk-python/sdk-python/temporalio/worker/_workflow_instance.py", line 2099, in execute_workflow
    return await input.run_fn(*args)
  File "/home/runner/work/sdk-python/sdk-python/tests/test_runtime.py", line 139, in run
    raise RuntimeError("Intentional error")
RuntimeError: Intentional error
WARNING  temporalio.worker._workflow_instance:_workflow_instance.py:385 Failed activation on workflow TaskFailWorkflow with ID workflow-e1bc361e-4c8b-46e0-9514-ae165d8ae93c and run ID d4c1a1d1-aa1a-4d43-b899-f30781bb1588
Traceback (most recent call last):
  File "/home/runner/work/sdk-python/sdk-python/temporalio/worker/_workflow_instance.py", line 351, in activate
    self._run_once(check_conditions=index == 1 or index == 2)
  File "/home/runner/work/sdk-python/sdk-python/temporalio/worker/_workflow_instance.py", line 1749, in _run_once
    raise self._current_activation_error
  File "/home/runner/work/sdk-python/sdk-python/temporalio/worker/_workflow_instance.py", line 1767, in _run_top_level_workflow_function
    await coro
  File "/home/runner/work/sdk-python/sdk-python/temporalio/worker/_workflow_instance.py", line 831, in run_workflow
    result = await self._inbound.execute_workflow(input)
  File "/home/runner/work/sdk-python/sdk-python/temporalio/worker/_workflow_instance.py", line 2099, in execute_workflow
    return await input.run_fn(*args)
  File "/home/runner/work/sdk-python/sdk-python/tests/test_runtime.py", line 139, in run
    raise RuntimeError("Intentional error")
RuntimeError: Intentional error
DEBUG    temporalio.worker._workflow:_workflow.py:299 Evicting workflow with run ID d4c1a1d1-aa1a-4d43-b899-f30781bb1588, message: Workflow activation completion failed: Failure { failure: Some(Failure { message: "Intentional error", source: "", stack_trace: "  File \"/home/runner/work/sdk-python/sdk-python/temporalio/worker/_workflow_instance.py\", line 351, in activate\n    self._run_once(check_conditions=index == 1 or index == 2)\n\n  File \"/home/runner/work/sdk-python/sdk-python/temporalio/worker/_workflow_instance.py\", line 1749, in _run_once\n    raise self._current_activation_error\n\n  File \"/home/runner/work/sdk-python/sdk-python/temporalio/worker/_workflow_instance.py\", line 1767, in _run_top_level_workflow_function\n    await coro\n\n  File \"/home/runner/work/sdk-python/sdk-python/temporalio/worker/_workflow_instance.py\", line 831, in run_workflow\n    result = await self._inbound.execute_workflow(input)\n\n  File \"/home/runner/work/sdk-python/sdk-python/temporalio/worker/_workflow_instance.py\", line 2099, in execute_workflow\n    return await input.run_fn(*args)\n\n  File \"/home/runner/work/sdk-python/sdk-python/tests/test_runtime.py\", line 139, in run\n    raise RuntimeError(\"Intentional error\")\n", encoded_attributes: None, cause: None, failure_info: Some(ApplicationFailureInfo(ApplicationFailureInfo { r#type: "RuntimeError", non_retryable: false, details: None, next_retry_delay: None })) }), force_cause: Unspecified }
INFO     temporalio.worker._worker:_worker.py:523 Beginning worker shutdown, will wait 0:00:00 before cancelling activities