DEBUG    temporalio.worker._workflow_instance:_workflow_instance.py:1788 Workflow raised failure with run ID d592d920-608c-4a5c-9158-85be6cceea4d
Traceback (most recent call last):
  File "/home/runner/work/sdk-python/sdk-python/temporalio/worker/_workflow_instance.py", line 1767, in _run_top_level_workflow_function
    await coro
  File "/home/runner/work/sdk-python/sdk-python/temporalio/worker/_workflow_instance.py", line 831, in run_workflow
    result = await self._inbound.execute_workflow(input)
  File "/home/runner/work/sdk-python/sdk-python/temporalio/testing/_workflow.py", line 493, in execute_workflow
    return await super().execute_workflow(input)
  File "/home/runner/work/sdk-python/sdk-python/temporalio/worker/_interceptor.py", line 328, in execute_workflow
    return await self.next.execute_workflow(input)
  File "/home/runner/work/sdk-python/sdk-python/temporalio/worker/_workflow_instance.py", line 2099, in execute_workflow
    return await input.run_fn(*args)
  File "/home/runner/work/sdk-python/sdk-python/tests/worker/test_workflow.py", line 5460, in run
    await workflow.wait_condition(workflow.all_handlers_finished)
  File "/home/runner/work/sdk-python/sdk-python/temporalio/workflow.py", line 1077, in wait_condition
    await _Runtime.current().workflow_wait_condition(
  File "/home/runner/work/sdk-python/sdk-python/temporalio/worker/_workflow_instance.py", line 1391, in workflow_wait_condition
    await asyncio.wait_for(fut, timeout)
  File "/opt/hostedtoolcache/Python/3.8.18/arm64/lib/python3.8/asyncio/tasks.py", line 455, in wait_for
    return await fut
asyncio.exceptions.CancelledError
INFO     temporalio.worker._worker:_worker.py:523 Beginning worker shutdown, will wait 0:00:00 before cancelling activities