DEBUG    temporalio.worker._activity:_activity.py:276 Running activity kill_my_process (token b'\x00\x07default\x00$441fcbe7-bd3f-4d8c-a536-075858d1500b\x00$d00789f8-22da-45f0-9175-a038d5e158e7\x00\x00\x00\x00\x00\x00\x00\x05\x00\x00\x00\x01')
DEBUG    temporalio.activity:_activity.py:440 Starting activity ({'activity_id': '1', 'activity_type': 'kill_my_process', 'attempt': 1, 'namespace': 'default', 'task_queue': '140c65d7-5de8-4b1e-b8c7-023d3e44fe71', 'workflow_id': '441fcbe7-bd3f-4d8c-a536-075858d1500b', 'workflow_run_id': 'd00789f8-22da-45f0-9175-a038d5e158e7', 'workflow_type': 'kitchen_sink'})
WARNING  temporalio.activity:_activity.py:493 Completing activity as failed ({'activity_id': '1', 'activity_type': 'kill_my_process', 'attempt': 1, 'namespace': 'default', 'task_queue': '140c65d7-5de8-4b1e-b8c7-023d3e44fe71', 'workflow_id': '441fcbe7-bd3f-4d8c-a536-075858d1500b', 'workflow_run_id': 'd00789f8-22da-45f0-9175-a038d5e158e7', 'workflow_type': 'kitchen_sink'})
Traceback (most recent call last):
  File "/home/runner/work/sdk-python/sdk-python/temporalio/worker/_activity.py", line 453, in _run_activity
    result = await impl.execute_activity(input)
  File "/home/runner/work/sdk-python/sdk-python/temporalio/worker/_activity.py", line 705, in execute_activity
    return await loop.run_in_executor(input.executor, func, *args)
concurrent.futures.process.BrokenProcessPool: A process in the process pool was terminated abruptly while the future was running or pending.
DEBUG    temporalio.worker._activity:_activity.py:527 Completing activity with completion: task_token: "\000\007default\000$441fcbe7-bd3f-4d8c-a536-075858d1500b\000$d00789f8-22da-45f0-9175-a038d5e158e7\000\000\000\000\000\000\000\005\000\000\000\001"
result {
  failed {
    failure {
      message: "A process in the process pool was terminated abruptly while the future was running or pending."
      stack_trace: "  File \"/home/runner/work/sdk-python/sdk-python/temporalio/worker/_activity.py\", line 453, in _run_activity\n    result = await impl.execute_activity(input)\n\n  File \"/home/runner/work/sdk-python/sdk-python/temporalio/worker/_activity.py\", line 705, in execute_activity\n    return await loop.run_in_executor(input.executor, func, *args)\n"
      application_failure_info {
        type: "BrokenProcessPool"
      }
    }
  }
}

ERROR    temporalio.worker._worker:_worker.py:508 Worker failed, shutting down
Traceback (most recent call last):
  File "/home/runner/work/sdk-python/sdk-python/temporalio/worker/_activity.py", line 161, in run
    await exception_task
  File "/home/runner/work/sdk-python/sdk-python/temporalio/worker/_activity.py", line 143, in raise_from_queue
    raise await self._fail_worker_exception_queue.get()
  File "/home/runner/work/sdk-python/sdk-python/temporalio/worker/_activity.py", line 453, in _run_activity
    result = await impl.execute_activity(input)
  File "/home/runner/work/sdk-python/sdk-python/temporalio/worker/_activity.py", line 705, in execute_activity
    return await loop.run_in_executor(input.executor, func, *args)
concurrent.futures.process.BrokenProcessPool: A process in the process pool was terminated abruptly while the future was running or pending.

The above exception was the direct cause of the following exception:

Traceback (most recent call last):
  File "/home/runner/work/sdk-python/sdk-python/temporalio/worker/_activity.py", line 182, in run
    raise RuntimeError("Activity worker failed") from err
RuntimeError: Activity worker failed
INFO     temporalio.worker._worker:_worker.py:523 Beginning worker shutdown, will wait 0:00:02 before cancelling activities
DEBUG    temporalio.worker._workflow_instance:_workflow_instance.py:1788 Workflow raised failure with run ID d00789f8-22da-45f0-9175-a038d5e158e7
temporalio.exceptions.ApplicationError: BrokenProcessPool: A process in the process pool was terminated abruptly while the future was running or pending.

The above exception was the direct cause of the following exception:

Traceback (most recent call last):
  File "/home/runner/work/sdk-python/sdk-python/temporalio/worker/_workflow_instance.py", line 1767, in _run_top_level_workflow_function
    await coro
  File "/home/runner/work/sdk-python/sdk-python/temporalio/worker/_workflow_instance.py", line 831, in run_workflow
    result = await self._inbound.execute_workflow(input)
  File "/home/runner/work/sdk-python/sdk-python/temporalio/testing/_workflow.py", line 493, in execute_workflow
    return await super().execute_workflow(input)
  File "/home/runner/work/sdk-python/sdk-python/temporalio/worker/_interceptor.py", line 328, in execute_workflow
    return await self.next.execute_workflow(input)
  File "/home/runner/work/sdk-python/sdk-python/temporalio/worker/_workflow_instance.py", line 2099, in execute_workflow
    return await input.run_fn(*args)
  File "/home/runner/work/sdk-python/sdk-python/tests/helpers/worker.py", line 97, in run
    should_return, ret = await self.handle_action(params, action)
  File "/home/runner/work/sdk-python/sdk-python/tests/helpers/worker.py", line 204, in handle_action
    raise task.exception()  # type: ignore
  File "/home/runner/work/sdk-python/sdk-python/tests/helpers/worker.py", line 193, in run_activity
    last_result = await task
  File "/home/runner/work/sdk-python/sdk-python/temporalio/worker/_workflow_instance.py", line 1423, in run_activity
    return await asyncio.shield(handle._result_fut)
temporalio.exceptions.ActivityError: Activity task failed