DEBUG    temporalio.worker._activity:_activity.py:276 Running activity wait_forever (token b'\n$8aa290fa-b00f-4fa1-a139-85696fcc157a\x123workflow-1614714c-040e-490c-9a62-a69952401165_child\x1a$f2ec4367-27e7-4ed3-bb3f-107bff41706b \x05(\x012\x011B\x0cwait_foreverJ\x08\x08\x01\x10\xdf\xa4@\x18\x01')
DEBUG    temporalio.activity:_activity.py:440 Starting activity ({'activity_id': '1', 'activity_type': 'wait_forever', 'attempt': 1, 'namespace': 'default', 'task_queue': '924c21ae-4216-4c31-9f1d-0506cd65ffda', 'workflow_id': 'workflow-1614714c-040e-490c-9a62-a69952401165_child', 'workflow_run_id': 'f2ec4367-27e7-4ed3-bb3f-107bff41706b', 'workflow_type': 'UncaughtCancelWorkflow'})
DEBUG    temporalio.worker._workflow_instance:_workflow_instance.py:1788 Workflow raised failure with run ID f2ec4367-27e7-4ed3-bb3f-107bff41706b
temporalio.exceptions.CancelledError: Cancelled

The above exception was the direct cause of the following exception:

Traceback (most recent call last):
  File "/home/runner/work/sdk-python/sdk-python/temporalio/worker/_workflow_instance.py", line 1767, in _run_top_level_workflow_function
    await coro
  File "/home/runner/work/sdk-python/sdk-python/temporalio/worker/_workflow_instance.py", line 831, in run_workflow
    result = await self._inbound.execute_workflow(input)
  File "/home/runner/work/sdk-python/sdk-python/temporalio/testing/_workflow.py", line 493, in execute_workflow
    return await super().execute_workflow(input)
  File "/home/runner/work/sdk-python/sdk-python/temporalio/worker/_interceptor.py", line 328, in execute_workflow
    return await self.next.execute_workflow(input)
  File "/home/runner/work/sdk-python/sdk-python/temporalio/worker/_workflow_instance.py", line 2099, in execute_workflow
    return await input.run_fn(*args)
  File "/home/runner/work/sdk-python/sdk-python/tests/worker/test_workflow.py", line 1046, in run
    await workflow.execute_activity(
  File "/home/runner/work/sdk-python/sdk-python/temporalio/workflow.py", line 2011, in execute_activity
    return await _Runtime.current().workflow_start_activity(
  File "/home/runner/work/sdk-python/sdk-python/temporalio/worker/_workflow_instance.py", line 1423, in run_activity
    return await asyncio.shield(handle._result_fut)
temporalio.exceptions.ActivityError: Activity cancelled
DEBUG    temporalio.worker._workflow_instance:_workflow_instance.py:1788 Workflow raised failure with run ID b63af3f9-4e4d-4afa-bdda-91d2a7ba07f2
temporalio.exceptions.CancelledError: Cancelled

The above exception was the direct cause of the following exception:

Traceback (most recent call last):
  File "/home/runner/work/sdk-python/sdk-python/temporalio/worker/_workflow_instance.py", line 1767, in _run_top_level_workflow_function
    await coro
  File "/home/runner/work/sdk-python/sdk-python/temporalio/worker/_workflow_instance.py", line 831, in run_workflow
    result = await self._inbound.execute_workflow(input)
  File "/home/runner/work/sdk-python/sdk-python/temporalio/testing/_workflow.py", line 493, in execute_workflow
    return await super().execute_workflow(input)
  File "/home/runner/work/sdk-python/sdk-python/temporalio/worker/_interceptor.py", line 328, in execute_workflow
    return await self.next.execute_workflow(input)
  File "/home/runner/work/sdk-python/sdk-python/temporalio/worker/_workflow_instance.py", line 2099, in execute_workflow
    return await input.run_fn(*args)
  File "/home/runner/work/sdk-python/sdk-python/tests/worker/test_workflow.py", line 1050, in run
    await workflow.execute_child_workflow(
  File "/home/runner/work/sdk-python/sdk-python/temporalio/workflow.py", line 3906, in execute_child_workflow
    return await handle
  File "/home/runner/work/sdk-python/sdk-python/temporalio/worker/_workflow_instance.py", line 1511, in run_child
    return await asyncio.shield(handle._result_fut)
temporalio.exceptions.ChildWorkflowError: Child Workflow execution cancelled
INFO     temporalio.worker._worker:_worker.py:523 Beginning worker shutdown, will wait 0:00:00 before cancelling activities
DEBUG    temporalio.worker._activity:_activity.py:216 Cancelling activity b'\n$8aa290fa-b00f-4fa1-a139-85696fcc157a\x123workflow-1614714c-040e-490c-9a62-a69952401165_child\x1a$f2ec4367-27e7-4ed3-bb3f-107bff41706b \x05(\x012\x011B\x0cwait_foreverJ\x08\x08\x01\x10\xdf\xa4@\x18\x01', reason: 3
DEBUG    temporalio.activity:_activity.py:486 Completing as cancelled ({'activity_id': '1', 'activity_type': 'wait_forever', 'attempt': 1, 'namespace': 'default', 'task_queue': '924c21ae-4216-4c31-9f1d-0506cd65ffda', 'workflow_id': 'workflow-1614714c-040e-490c-9a62-a69952401165_child', 'workflow_run_id': 'f2ec4367-27e7-4ed3-bb3f-107bff41706b', 'workflow_type': 'UncaughtCancelWorkflow'})
DEBUG    temporalio.worker._activity:_activity.py:527 Completing activity with completion: task_token: "\n$8aa290fa-b00f-4fa1-a139-85696fcc157a\0223workflow-1614714c-040e-490c-9a62-a69952401165_child\032$f2ec4367-27e7-4ed3-bb3f-107bff41706b \005(\0012\0011B\014wait_foreverJ\010\010\001\020\337\244@\030\001"
result {
  cancelled {
    failure {
      message: "Cancelled"
      canceled_failure_info {
      }
    }
  }
}