DEBUG    temporalio.worker._activity:_activity.py:276 Running activity raise_error (token b'\n$8aa290fa-b00f-4fa1-a139-85696fcc157a\x12$82996dcf-089b-47d5-b9f5-ccb5ab2decea\x1a$57164adf-c112-4451-95f6-c99f1e400c39 \x05(\x012\x011B\x0braise_errorJ\x08\x08\x01\x10\xf0\x8b@\x18\x01')
DEBUG    temporalio.activity:_activity.py:440 Starting activity ({'activity_id': '1', 'activity_type': 'raise_error', 'attempt': 1, 'namespace': 'default', 'task_queue': '1d0dc289-1530-4c4c-84e1-7badd80c6fbf', 'workflow_id': '82996dcf-089b-47d5-b9f5-ccb5ab2decea', 'workflow_run_id': '57164adf-c112-4451-95f6-c99f1e400c39', 'workflow_type': 'kitchen_sink'})
WARNING  temporalio.activity:_activity.py:493 Completing activity as failed ({'activity_id': '1', 'activity_type': 'raise_error', 'attempt': 1, 'namespace': 'default', 'task_queue': '1d0dc289-1530-4c4c-84e1-7badd80c6fbf', 'workflow_id': '82996dcf-089b-47d5-b9f5-ccb5ab2decea', 'workflow_run_id': '57164adf-c112-4451-95f6-c99f1e400c39', 'workflow_type': 'kitchen_sink'})
Traceback (most recent call last):
  File "/home/runner/work/sdk-python/sdk-python/temporalio/worker/_activity.py", line 453, in _run_activity
    result = await impl.execute_activity(input)
  File "/home/runner/work/sdk-python/sdk-python/temporalio/worker/_activity.py", line 711, in execute_activity
    return await input.fn(*input.args)
  File "/home/runner/work/sdk-python/sdk-python/tests/worker/test_activity.py", line 205, in raise_error
    raise RuntimeError("oh no!")
RuntimeError: oh no!
DEBUG    temporalio.worker._activity:_activity.py:527 Completing activity with completion: task_token: "\n$8aa290fa-b00f-4fa1-a139-85696fcc157a\022$82996dcf-089b-47d5-b9f5-ccb5ab2decea\032$57164adf-c112-4451-95f6-c99f1e400c39 \005(\0012\0011B\013raise_errorJ\010\010\001\020\360\213@\030\001"
result {
  failed {
    failure {
      message: "oh no!"
      stack_trace: "  File \"/home/runner/work/sdk-python/sdk-python/temporalio/worker/_activity.py\", line 453, in _run_activity\n    result = await impl.execute_activity(input)\n\n  File \"/home/runner/work/sdk-python/sdk-python/temporalio/worker/_activity.py\", line 711, in execute_activity\n    return await input.fn(*input.args)\n\n  File \"/home/runner/work/sdk-python/sdk-python/tests/worker/test_activity.py\", line 205, in raise_error\n    raise RuntimeError(\"oh no!\")\n"
      application_failure_info {
        type: "RuntimeError"
      }
    }
  }
}

DEBUG    temporalio.worker._workflow_instance:_workflow_instance.py:1788 Workflow raised failure with run ID 57164adf-c112-4451-95f6-c99f1e400c39
temporalio.exceptions.ApplicationError: RuntimeError: oh no!

The above exception was the direct cause of the following exception:

Traceback (most recent call last):
  File "/home/runner/work/sdk-python/sdk-python/temporalio/worker/_workflow_instance.py", line 1767, in _run_top_level_workflow_function
    await coro
  File "/home/runner/work/sdk-python/sdk-python/temporalio/worker/_workflow_instance.py", line 831, in run_workflow
    result = await self._inbound.execute_workflow(input)
  File "/home/runner/work/sdk-python/sdk-python/temporalio/testing/_workflow.py", line 493, in execute_workflow
    return await super().execute_workflow(input)
  File "/home/runner/work/sdk-python/sdk-python/temporalio/worker/_interceptor.py", line 328, in execute_workflow
    return await self.next.execute_workflow(input)
  File "/home/runner/work/sdk-python/sdk-python/temporalio/worker/_workflow_instance.py", line 2099, in execute_workflow
    return await input.run_fn(*args)
  File "/home/runner/work/sdk-python/sdk-python/tests/helpers/worker.py", line 97, in run
    should_return, ret = await self.handle_action(params, action)
  File "/home/runner/work/sdk-python/sdk-python/tests/helpers/worker.py", line 204, in handle_action
    raise task.exception()  # type: ignore
  File "/home/runner/work/sdk-python/sdk-python/tests/helpers/worker.py", line 193, in run_activity
    last_result = await task
  File "/home/runner/work/sdk-python/sdk-python/temporalio/worker/_workflow_instance.py", line 1423, in run_activity
    return await asyncio.shield(handle._result_fut)
temporalio.exceptions.ActivityError: Activity task failed
INFO     temporalio.worker._worker:_worker.py:523 Beginning worker shutdown, will wait 0:00:00 before cancelling activities